Not Found: /graf
Not Found: /tomo_statistics/graf
Internal Server Error: /tomo_statistics/graf_test/2/
Traceback (most recent call last):
  File "C:\Users\Samo\AppData\Local\Programs\Python\Python35\lib\site-packages\django\core\handlers\base.py", line 149, in get_response
    response = self.process_exception_by_middleware(e, request)
  File "C:\Users\Samo\AppData\Local\Programs\Python\Python35\lib\site-packages\django\core\handlers\base.py", line 147, in get_response
    response = wrapped_callback(request, *callback_args, **callback_kwargs)
  File "C:\Users\Samo\Desktop\projekt-tomo\projekt-tomo\web\tomo_statistics\views.py", line 15, in graph
    response = JsonResponse(course.json_za_graf())
  File "C:\Users\Samo\AppData\Local\Programs\Python\Python35\lib\site-packages\django\http\response.py", line 500, in __init__
    raise TypeError('In order to allow non-dict objects to be '
TypeError: In order to allow non-dict objects to be serialized set the safe parameter to False
Internal Server Error: /tomo_statistics/graf_test/2/
Traceback (most recent call last):
  File "C:\Users\Samo\AppData\Local\Programs\Python\Python35\lib\site-packages\django\core\handlers\base.py", line 149, in get_response
    response = self.process_exception_by_middleware(e, request)
  File "C:\Users\Samo\AppData\Local\Programs\Python\Python35\lib\site-packages\django\core\handlers\base.py", line 147, in get_response
    response = wrapped_callback(request, *callback_args, **callback_kwargs)
  File "C:\Users\Samo\Desktop\projekt-tomo\projekt-tomo\web\tomo_statistics\views.py", line 15, in graph
    response = JsonResponse(course.json_za_graf())
  File "C:\Users\Samo\AppData\Local\Programs\Python\Python35\lib\site-packages\django\http\response.py", line 500, in __init__
    raise TypeError('In order to allow non-dict objects to be '
TypeError: In order to allow non-dict objects to be serialized set the safe parameter to False
Internal Server Error: /tomo_statistics/graf_test/2/
Traceback (most recent call last):
  File "C:\Users\Samo\AppData\Local\Programs\Python\Python35\lib\site-packages\django\core\handlers\base.py", line 149, in get_response
    response = self.process_exception_by_middleware(e, request)
  File "C:\Users\Samo\AppData\Local\Programs\Python\Python35\lib\site-packages\django\core\handlers\base.py", line 147, in get_response
    response = wrapped_callback(request, *callback_args, **callback_kwargs)
  File "C:\Users\Samo\Desktop\projekt-tomo\projekt-tomo\web\tomo_statistics\views.py", line 15, in graph
    response = JsonResponse(course.json_za_graf())
  File "C:\Users\Samo\AppData\Local\Programs\Python\Python35\lib\site-packages\django\http\response.py", line 500, in __init__
    raise TypeError('In order to allow non-dict objects to be '
TypeError: In order to allow non-dict objects to be serialized set the safe parameter to False
Internal Server Error: /tomo_statistics/graf_test/2/
Traceback (most recent call last):
  File "C:\Users\Samo\AppData\Local\Programs\Python\Python35\lib\site-packages\django\core\handlers\base.py", line 149, in get_response
    response = self.process_exception_by_middleware(e, request)
  File "C:\Users\Samo\AppData\Local\Programs\Python\Python35\lib\site-packages\django\core\handlers\base.py", line 147, in get_response
    response = wrapped_callback(request, *callback_args, **callback_kwargs)
  File "C:\Users\Samo\Desktop\projekt-tomo\projekt-tomo\web\tomo_statistics\views.py", line 16, in graph
    return render(request, 'tomo_statistics/graf.html', course.json_za_graf())
  File "C:\Users\Samo\AppData\Local\Programs\Python\Python35\lib\site-packages\django\shortcuts.py", line 67, in render
    template_name, context, request=request, using=using)
  File "C:\Users\Samo\AppData\Local\Programs\Python\Python35\lib\site-packages\django\template\loader.py", line 97, in render_to_string
    return template.render(context, request)
  File "C:\Users\Samo\AppData\Local\Programs\Python\Python35\lib\site-packages\django\template\backends\django.py", line 92, in render
    context = make_context(context, request)
  File "C:\Users\Samo\AppData\Local\Programs\Python\Python35\lib\site-packages\django\template\context.py", line 291, in make_context
    context.push(original_context)
  File "C:\Users\Samo\AppData\Local\Programs\Python\Python35\lib\site-packages\django\template\context.py", line 61, in push
    return ContextDict(self, *dicts, **kwargs)
  File "C:\Users\Samo\AppData\Local\Programs\Python\Python35\lib\site-packages\django\template\context.py", line 20, in __init__
    super(ContextDict, self).__init__(*args, **kwargs)
ValueError: dictionary update sequence element #0 has length 1; 2 is required
Internal Server Error: /tomo_statistics/graf_test/2/
Traceback (most recent call last):
  File "C:\Users\Samo\AppData\Local\Programs\Python\Python35\lib\site-packages\django\core\handlers\base.py", line 149, in get_response
    response = self.process_exception_by_middleware(e, request)
  File "C:\Users\Samo\AppData\Local\Programs\Python\Python35\lib\site-packages\django\core\handlers\base.py", line 147, in get_response
    response = wrapped_callback(request, *callback_args, **callback_kwargs)
  File "C:\Users\Samo\Desktop\projekt-tomo\projekt-tomo\web\tomo_statistics\views.py", line 15, in graph
    response = JsonResponse(course.json_za_graf(), safe = False)
  File "C:\Users\Samo\Desktop\projekt-tomo\projekt-tomo\web\tomo_statistics\models.py", line 59, in json_za_graf
    test = {'niz' : str(slovar[solved_atleast])}
NameError: name 'solved_atleast' is not defined
Internal Server Error: /tomo_statistics/graf_test/2/
Traceback (most recent call last):
  File "C:\Users\Samo\AppData\Local\Programs\Python\Python35\lib\site-packages\django\core\handlers\base.py", line 149, in get_response
    response = self.process_exception_by_middleware(e, request)
  File "C:\Users\Samo\AppData\Local\Programs\Python\Python35\lib\site-packages\django\core\handlers\base.py", line 147, in get_response
    response = wrapped_callback(request, *callback_args, **callback_kwargs)
  File "C:\Users\Samo\Desktop\projekt-tomo\projekt-tomo\web\tomo_statistics\views.py", line 15, in graph
    response = JsonResponse(course.json_za_graf(), safe = False)
  File "C:\Users\Samo\AppData\Local\Programs\Python\Python35\lib\site-packages\django\http\response.py", line 505, in __init__
    data = json.dumps(data, cls=encoder, **json_dumps_params)
  File "C:\Users\Samo\AppData\Local\Programs\Python\Python35\lib\json\__init__.py", line 237, in dumps
    **kw).encode(obj)
  File "C:\Users\Samo\AppData\Local\Programs\Python\Python35\lib\json\encoder.py", line 198, in encode
    chunks = self.iterencode(o, _one_shot=True)
  File "C:\Users\Samo\AppData\Local\Programs\Python\Python35\lib\json\encoder.py", line 256, in iterencode
    return _iterencode(o, 0)
  File "C:\Users\Samo\AppData\Local\Programs\Python\Python35\lib\site-packages\django\core\serializers\json.py", line 115, in default
    return super(DjangoJSONEncoder, self).default(o)
  File "C:\Users\Samo\AppData\Local\Programs\Python\Python35\lib\json\encoder.py", line 179, in default
    raise TypeError(repr(o) + " is not JSON serializable")
TypeError: [<ProblemSet: Uporaba seznamov>, <ProblemSet: Nizi uporaba>, <ProblemSet: Izpeljani seznami>, <ProblemSet: Rekurzija>, <ProblemSet: Objektno programiranje>, <ProblemSet: Algoritmi>] is not JSON serializable
Internal Server Error: /tomo_statistics/graf_test/2/
Traceback (most recent call last):
  File "C:\Users\Samo\AppData\Local\Programs\Python\Python35\lib\site-packages\django\core\handlers\base.py", line 149, in get_response
    response = self.process_exception_by_middleware(e, request)
  File "C:\Users\Samo\AppData\Local\Programs\Python\Python35\lib\site-packages\django\core\handlers\base.py", line 147, in get_response
    response = wrapped_callback(request, *callback_args, **callback_kwargs)
  File "C:\Users\Samo\Desktop\projekt-tomo\projekt-tomo\web\tomo_statistics\views.py", line 15, in graph
    return render(request, 'tomo_statistics/graf.html', course.json_za_graf())
  File "C:\Users\Samo\AppData\Local\Programs\Python\Python35\lib\site-packages\django\shortcuts.py", line 67, in render
    template_name, context, request=request, using=using)
  File "C:\Users\Samo\AppData\Local\Programs\Python\Python35\lib\site-packages\django\template\loader.py", line 96, in render_to_string
    template = get_template(template_name, using=using)
  File "C:\Users\Samo\AppData\Local\Programs\Python\Python35\lib\site-packages\django\template\loader.py", line 32, in get_template
    return engine.get_template(template_name, dirs)
  File "C:\Users\Samo\AppData\Local\Programs\Python\Python35\lib\site-packages\django\template\backends\django.py", line 40, in get_template
    return Template(self.engine.get_template(template_name, dirs), self)
  File "C:\Users\Samo\AppData\Local\Programs\Python\Python35\lib\site-packages\django\template\engine.py", line 190, in get_template
    template, origin = self.find_template(template_name, dirs)
  File "C:\Users\Samo\AppData\Local\Programs\Python\Python35\lib\site-packages\django\template\engine.py", line 157, in find_template
    name, template_dirs=dirs, skip=skip,
  File "C:\Users\Samo\AppData\Local\Programs\Python\Python35\lib\site-packages\django\template\loaders\base.py", line 46, in get_template
    contents, origin, origin.template_name, self.engine,
  File "C:\Users\Samo\AppData\Local\Programs\Python\Python35\lib\site-packages\django\template\base.py", line 189, in __init__
    self.nodelist = self.compile_nodelist()
  File "C:\Users\Samo\AppData\Local\Programs\Python\Python35\lib\site-packages\django\template\base.py", line 231, in compile_nodelist
    return parser.parse()
  File "C:\Users\Samo\AppData\Local\Programs\Python\Python35\lib\site-packages\django\template\base.py", line 516, in parse
    raise self.error(token, e)
  File "C:\Users\Samo\AppData\Local\Programs\Python\Python35\lib\site-packages\django\template\base.py", line 514, in parse
    compiled_result = compile_func(self, token)
  File "C:\Users\Samo\AppData\Local\Programs\Python\Python35\lib\site-packages\django\template\loader_tags.py", line 267, in do_extends
    nodelist = parser.parse()
  File "C:\Users\Samo\AppData\Local\Programs\Python\Python35\lib\site-packages\django\template\base.py", line 516, in parse
    raise self.error(token, e)
  File "C:\Users\Samo\AppData\Local\Programs\Python\Python35\lib\site-packages\django\template\base.py", line 514, in parse
    compiled_result = compile_func(self, token)
  File "C:\Users\Samo\AppData\Local\Programs\Python\Python35\lib\site-packages\django\template\loader_tags.py", line 241, in do_block
    nodelist = parser.parse(('endblock',))
  File "C:\Users\Samo\AppData\Local\Programs\Python\Python35\lib\site-packages\django\template\base.py", line 487, in parse
    raise self.error(token, e)
  File "C:\Users\Samo\AppData\Local\Programs\Python\Python35\lib\site-packages\django\template\base.py", line 485, in parse
    filter_expression = self.compile_filter(token.contents)
  File "C:\Users\Samo\AppData\Local\Programs\Python\Python35\lib\site-packages\django\template\base.py", line 601, in compile_filter
    return FilterExpression(token, self)
  File "C:\Users\Samo\AppData\Local\Programs\Python\Python35\lib\site-packages\django\template\base.py", line 695, in __init__
    filter_func = parser.find_filter(filter_name)
  File "C:\Users\Samo\AppData\Local\Programs\Python\Python35\lib\site-packages\django\template\base.py", line 607, in find_filter
    raise TemplateSyntaxError("Invalid filter: '%s'" % filter_name)
django.template.exceptions.TemplateSyntaxError: Invalid filter: 'json'
Internal Server Error: /tomo_statistics/graf_test/2/
Traceback (most recent call last):
  File "C:\Users\Samo\AppData\Local\Programs\Python\Python35\lib\site-packages\django\core\handlers\base.py", line 149, in get_response
    response = self.process_exception_by_middleware(e, request)
  File "C:\Users\Samo\AppData\Local\Programs\Python\Python35\lib\site-packages\django\core\handlers\base.py", line 147, in get_response
    response = wrapped_callback(request, *callback_args, **callback_kwargs)
  File "C:\Users\Samo\Desktop\projekt-tomo\projekt-tomo\web\tomo_statistics\views.py", line 21, in graph
    json_data = json.dumps(course.statistika())
  File "C:\Users\Samo\AppData\Local\Programs\Python\Python35\lib\json\__init__.py", line 230, in dumps
    return _default_encoder.encode(obj)
  File "C:\Users\Samo\AppData\Local\Programs\Python\Python35\lib\json\encoder.py", line 198, in encode
    chunks = self.iterencode(o, _one_shot=True)
  File "C:\Users\Samo\AppData\Local\Programs\Python\Python35\lib\json\encoder.py", line 256, in iterencode
    return _iterencode(o, 0)
  File "C:\Users\Samo\AppData\Local\Programs\Python\Python35\lib\json\encoder.py", line 179, in default
    raise TypeError(repr(o) + " is not JSON serializable")
TypeError: [<User: sbradleyjo>, <User: rfieldsbq>, <User: efox81>, <User: agordonc2>, <User: bhudson1w>, <User: rpowell3b>, <User: jreidcs>, <User: cruizi3>, <User: asimpson1i>, <User: jwestd9>] is not JSON serializable
Internal Server Error: /tomo_statistics/graf_test/2/
Traceback (most recent call last):
  File "C:\Users\Samo\AppData\Local\Programs\Python\Python35\lib\site-packages\django\core\handlers\base.py", line 149, in get_response
    response = self.process_exception_by_middleware(e, request)
  File "C:\Users\Samo\AppData\Local\Programs\Python\Python35\lib\site-packages\django\core\handlers\base.py", line 147, in get_response
    response = wrapped_callback(request, *callback_args, **callback_kwargs)
  File "C:\Users\Samo\Desktop\projekt-tomo\projekt-tomo\web\tomo_statistics\views.py", line 21, in graph
    json_data = json.dumps(course.statistika())
  File "C:\Users\Samo\AppData\Local\Programs\Python\Python35\lib\json\__init__.py", line 230, in dumps
    return _default_encoder.encode(obj)
  File "C:\Users\Samo\AppData\Local\Programs\Python\Python35\lib\json\encoder.py", line 198, in encode
    chunks = self.iterencode(o, _one_shot=True)
  File "C:\Users\Samo\AppData\Local\Programs\Python\Python35\lib\json\encoder.py", line 256, in iterencode
    return _iterencode(o, 0)
  File "C:\Users\Samo\AppData\Local\Programs\Python\Python35\lib\json\encoder.py", line 179, in default
    raise TypeError(repr(o) + " is not JSON serializable")
TypeError: [<ProblemSet: Uporaba seznamov>, <ProblemSet: Nizi uporaba>, <ProblemSet: Izpeljani seznami>, <ProblemSet: Rekurzija>, <ProblemSet: Objektno programiranje>, <ProblemSet: Algoritmi>] is not JSON serializable
Internal Server Error: /tomo_statistics/graf_test/2/
Traceback (most recent call last):
  File "C:\Users\Samo\AppData\Local\Programs\Python\Python35\lib\site-packages\django\core\handlers\base.py", line 149, in get_response
    response = self.process_exception_by_middleware(e, request)
  File "C:\Users\Samo\AppData\Local\Programs\Python\Python35\lib\site-packages\django\core\handlers\base.py", line 147, in get_response
    response = wrapped_callback(request, *callback_args, **callback_kwargs)
  File "C:\Users\Samo\Desktop\projekt-tomo\projekt-tomo\web\tomo_statistics\views.py", line 21, in graph
    json_data = json.dump(course.statistika()['solved_atleast'])
TypeError: dump() missing 1 required positional argument: 'fp'
Not Found: /tomo_statistics//graph_test/2/
Not Found: /tomo_statistics//graf_test/2/
Not Found: /favicon.ico
Internal Server Error: /tomo_statistics/17/
Traceback (most recent call last):
  File "C:\Users\Samo\AppData\Local\Programs\Python\Python35\lib\site-packages\django\core\handlers\base.py", line 149, in get_response
    response = self.process_exception_by_middleware(e, request)
  File "C:\Users\Samo\AppData\Local\Programs\Python\Python35\lib\site-packages\django\core\handlers\base.py", line 147, in get_response
    response = wrapped_callback(request, *callback_args, **callback_kwargs)
  File "C:\Users\Samo\Desktop\projekt-tomo\projekt-tomo\web\tomo_statistics\views.py", line 12, in test_view
    return render(request, 'tomo_statistics/statistika_course.html', course.problem_success())
  File "C:\Users\Samo\Desktop\projekt-tomo\projekt-tomo\web\tomo_statistics\models.py", line 67, in problem_success
    for problem_set in problem_sets:
  File "C:\Users\Samo\AppData\Local\Programs\Python\Python35\lib\site-packages\django\db\models\query.py", line 258, in __iter__
    self._fetch_all()
  File "C:\Users\Samo\AppData\Local\Programs\Python\Python35\lib\site-packages\django\db\models\query.py", line 1076, in _fetch_all
    self._prefetch_related_objects()
  File "C:\Users\Samo\AppData\Local\Programs\Python\Python35\lib\site-packages\django\db\models\query.py", line 656, in _prefetch_related_objects
    prefetch_related_objects(self._result_cache, self._prefetch_related_lookups)
  File "C:\Users\Samo\AppData\Local\Programs\Python\Python35\lib\site-packages\django\db\models\query.py", line 1454, in prefetch_related_objects
    "prefetch_related()." % lookup.prefetch_through)
ValueError: 'problems__parts__attempts__valid' does not resolve to an item that supports prefetching - this is an invalid parameter to prefetch_related().
Internal Server Error: /tomo_statistics/2/
Traceback (most recent call last):
  File "C:\Users\Samo\AppData\Local\Programs\Python\Python35\lib\site-packages\django\core\handlers\base.py", line 149, in get_response
    response = self.process_exception_by_middleware(e, request)
  File "C:\Users\Samo\AppData\Local\Programs\Python\Python35\lib\site-packages\django\core\handlers\base.py", line 147, in get_response
    response = wrapped_callback(request, *callback_args, **callback_kwargs)
  File "C:\Users\Samo\Desktop\projekt-tomo\projekt-tomo\web\tomo_statistics\views.py", line 12, in test_view
    return render(request, 'tomo_statistics/statistika_course.html', course.problem_success())
  File "C:\Users\Samo\Desktop\projekt-tomo\projekt-tomo\web\tomo_statistics\models.py", line 67, in problem_success
    for problem_set in problem_sets:
  File "C:\Users\Samo\AppData\Local\Programs\Python\Python35\lib\site-packages\django\db\models\query.py", line 258, in __iter__
    self._fetch_all()
  File "C:\Users\Samo\AppData\Local\Programs\Python\Python35\lib\site-packages\django\db\models\query.py", line 1076, in _fetch_all
    self._prefetch_related_objects()
  File "C:\Users\Samo\AppData\Local\Programs\Python\Python35\lib\site-packages\django\db\models\query.py", line 656, in _prefetch_related_objects
    prefetch_related_objects(self._result_cache, self._prefetch_related_lookups)
  File "C:\Users\Samo\AppData\Local\Programs\Python\Python35\lib\site-packages\django\db\models\query.py", line 1454, in prefetch_related_objects
    "prefetch_related()." % lookup.prefetch_through)
ValueError: 'problems__parts__attempts__valid' does not resolve to an item that supports prefetching - this is an invalid parameter to prefetch_related().
Internal Server Error: /tomo_statistics/17/
Traceback (most recent call last):
  File "C:\Users\Samo\AppData\Local\Programs\Python\Python35\lib\site-packages\django\core\handlers\base.py", line 149, in get_response
    response = self.process_exception_by_middleware(e, request)
  File "C:\Users\Samo\AppData\Local\Programs\Python\Python35\lib\site-packages\django\core\handlers\base.py", line 147, in get_response
    response = wrapped_callback(request, *callback_args, **callback_kwargs)
  File "C:\Users\Samo\Desktop\projekt-tomo\projekt-tomo\web\tomo_statistics\views.py", line 12, in test_view
    json_correct = json.dumps(course.problem_success()['correct_submissions'])
  File "C:\Users\Samo\Desktop\projekt-tomo\projekt-tomo\web\tomo_statistics\models.py", line 64, in problem_success
    data = [['Correct_submissions', 'Incorrect_submissions', { role: 'annotation' }]]
NameError: name 'role' is not defined
Not Found: /favicon.ico
Not Found: /favicon.ico
Not Found: /favicon.ico
Internal Server Error: /admin/users/user/add/
Traceback (most recent call last):
  File "C:\Users\Samo\AppData\Local\Programs\Python\Python35\lib\site-packages\django\core\handlers\base.py", line 149, in get_response
    response = self.process_exception_by_middleware(e, request)
  File "C:\Users\Samo\AppData\Local\Programs\Python\Python35\lib\site-packages\django\core\handlers\base.py", line 147, in get_response
    response = wrapped_callback(request, *callback_args, **callback_kwargs)
  File "C:\Users\Samo\AppData\Local\Programs\Python\Python35\lib\site-packages\django\contrib\admin\options.py", line 541, in wrapper
    return self.admin_site.admin_view(view)(*args, **kwargs)
  File "C:\Users\Samo\AppData\Local\Programs\Python\Python35\lib\site-packages\django\utils\decorators.py", line 149, in _wrapped_view
    response = view_func(request, *args, **kwargs)
  File "C:\Users\Samo\AppData\Local\Programs\Python\Python35\lib\site-packages\django\views\decorators\cache.py", line 57, in _wrapped_view_func
    response = view_func(request, *args, **kwargs)
  File "C:\Users\Samo\AppData\Local\Programs\Python\Python35\lib\site-packages\django\contrib\admin\sites.py", line 244, in inner
    return view(request, *args, **kwargs)
  File "C:\Users\Samo\AppData\Local\Programs\Python\Python35\lib\site-packages\django\utils\decorators.py", line 67, in _wrapper
    return bound_func(*args, **kwargs)
  File "C:\Users\Samo\AppData\Local\Programs\Python\Python35\lib\site-packages\django\views\decorators\debug.py", line 76, in sensitive_post_parameters_wrapper
    return view(request, *args, **kwargs)
  File "C:\Users\Samo\AppData\Local\Programs\Python\Python35\lib\site-packages\django\utils\decorators.py", line 63, in bound_func
    return func.__get__(self, type(self))(*args2, **kwargs2)
  File "C:\Users\Samo\AppData\Local\Programs\Python\Python35\lib\site-packages\django\utils\decorators.py", line 67, in _wrapper
    return bound_func(*args, **kwargs)
  File "C:\Users\Samo\AppData\Local\Programs\Python\Python35\lib\site-packages\django\utils\decorators.py", line 149, in _wrapped_view
    response = view_func(request, *args, **kwargs)
  File "C:\Users\Samo\AppData\Local\Programs\Python\Python35\lib\site-packages\django\utils\decorators.py", line 63, in bound_func
    return func.__get__(self, type(self))(*args2, **kwargs2)
  File "C:\Users\Samo\AppData\Local\Programs\Python\Python35\lib\contextlib.py", line 30, in inner
    return func(*args, **kwds)
  File "C:\Users\Samo\AppData\Local\Programs\Python\Python35\lib\site-packages\django\contrib\auth\admin.py", line 128, in add_view
    extra_context)
  File "C:\Users\Samo\AppData\Local\Programs\Python\Python35\lib\site-packages\django\contrib\admin\options.py", line 1437, in add_view
    return self.changeform_view(request, None, form_url, extra_context)
  File "C:\Users\Samo\AppData\Local\Programs\Python\Python35\lib\site-packages\django\utils\decorators.py", line 67, in _wrapper
    return bound_func(*args, **kwargs)
  File "C:\Users\Samo\AppData\Local\Programs\Python\Python35\lib\site-packages\django\utils\decorators.py", line 149, in _wrapped_view
    response = view_func(request, *args, **kwargs)
  File "C:\Users\Samo\AppData\Local\Programs\Python\Python35\lib\site-packages\django\utils\decorators.py", line 63, in bound_func
    return func.__get__(self, type(self))(*args2, **kwargs2)
  File "C:\Users\Samo\AppData\Local\Programs\Python\Python35\lib\contextlib.py", line 30, in inner
    return func(*args, **kwds)
  File "C:\Users\Samo\AppData\Local\Programs\Python\Python35\lib\site-packages\django\contrib\admin\options.py", line 1370, in changeform_view
    if form.is_valid():
  File "C:\Users\Samo\AppData\Local\Programs\Python\Python35\lib\site-packages\django\forms\forms.py", line 161, in is_valid
    return self.is_bound and not self.errors
  File "C:\Users\Samo\AppData\Local\Programs\Python\Python35\lib\site-packages\django\forms\forms.py", line 153, in errors
    self.full_clean()
  File "C:\Users\Samo\AppData\Local\Programs\Python\Python35\lib\site-packages\django\forms\forms.py", line 362, in full_clean
    self._clean_fields()
  File "C:\Users\Samo\AppData\Local\Programs\Python\Python35\lib\site-packages\django\forms\forms.py", line 383, in _clean_fields
    value = getattr(self, 'clean_%s' % name)()
  File "C:\Users\Samo\Desktop\projekt-tomo\projekt-tomo\web\users\admin.py", line 18, in clean_username
    raise forms.ValidationError(self.error_messages['duplicate_username'])
KeyError: 'duplicate_username'
Internal Server Error: /admin/users/user/add/
Traceback (most recent call last):
  File "C:\Users\Samo\AppData\Local\Programs\Python\Python35\lib\site-packages\django\core\handlers\base.py", line 149, in get_response
    response = self.process_exception_by_middleware(e, request)
  File "C:\Users\Samo\AppData\Local\Programs\Python\Python35\lib\site-packages\django\core\handlers\base.py", line 147, in get_response
    response = wrapped_callback(request, *callback_args, **callback_kwargs)
  File "C:\Users\Samo\AppData\Local\Programs\Python\Python35\lib\site-packages\django\contrib\admin\options.py", line 541, in wrapper
    return self.admin_site.admin_view(view)(*args, **kwargs)
  File "C:\Users\Samo\AppData\Local\Programs\Python\Python35\lib\site-packages\django\utils\decorators.py", line 149, in _wrapped_view
    response = view_func(request, *args, **kwargs)
  File "C:\Users\Samo\AppData\Local\Programs\Python\Python35\lib\site-packages\django\views\decorators\cache.py", line 57, in _wrapped_view_func
    response = view_func(request, *args, **kwargs)
  File "C:\Users\Samo\AppData\Local\Programs\Python\Python35\lib\site-packages\django\contrib\admin\sites.py", line 244, in inner
    return view(request, *args, **kwargs)
  File "C:\Users\Samo\AppData\Local\Programs\Python\Python35\lib\site-packages\django\utils\decorators.py", line 67, in _wrapper
    return bound_func(*args, **kwargs)
  File "C:\Users\Samo\AppData\Local\Programs\Python\Python35\lib\site-packages\django\views\decorators\debug.py", line 76, in sensitive_post_parameters_wrapper
    return view(request, *args, **kwargs)
  File "C:\Users\Samo\AppData\Local\Programs\Python\Python35\lib\site-packages\django\utils\decorators.py", line 63, in bound_func
    return func.__get__(self, type(self))(*args2, **kwargs2)
  File "C:\Users\Samo\AppData\Local\Programs\Python\Python35\lib\site-packages\django\utils\decorators.py", line 67, in _wrapper
    return bound_func(*args, **kwargs)
  File "C:\Users\Samo\AppData\Local\Programs\Python\Python35\lib\site-packages\django\utils\decorators.py", line 149, in _wrapped_view
    response = view_func(request, *args, **kwargs)
  File "C:\Users\Samo\AppData\Local\Programs\Python\Python35\lib\site-packages\django\utils\decorators.py", line 63, in bound_func
    return func.__get__(self, type(self))(*args2, **kwargs2)
  File "C:\Users\Samo\AppData\Local\Programs\Python\Python35\lib\contextlib.py", line 30, in inner
    return func(*args, **kwds)
  File "C:\Users\Samo\AppData\Local\Programs\Python\Python35\lib\site-packages\django\contrib\auth\admin.py", line 128, in add_view
    extra_context)
  File "C:\Users\Samo\AppData\Local\Programs\Python\Python35\lib\site-packages\django\contrib\admin\options.py", line 1437, in add_view
    return self.changeform_view(request, None, form_url, extra_context)
  File "C:\Users\Samo\AppData\Local\Programs\Python\Python35\lib\site-packages\django\utils\decorators.py", line 67, in _wrapper
    return bound_func(*args, **kwargs)
  File "C:\Users\Samo\AppData\Local\Programs\Python\Python35\lib\site-packages\django\utils\decorators.py", line 149, in _wrapped_view
    response = view_func(request, *args, **kwargs)
  File "C:\Users\Samo\AppData\Local\Programs\Python\Python35\lib\site-packages\django\utils\decorators.py", line 63, in bound_func
    return func.__get__(self, type(self))(*args2, **kwargs2)
  File "C:\Users\Samo\AppData\Local\Programs\Python\Python35\lib\contextlib.py", line 30, in inner
    return func(*args, **kwds)
  File "C:\Users\Samo\AppData\Local\Programs\Python\Python35\lib\site-packages\django\contrib\admin\options.py", line 1370, in changeform_view
    if form.is_valid():
  File "C:\Users\Samo\AppData\Local\Programs\Python\Python35\lib\site-packages\django\forms\forms.py", line 161, in is_valid
    return self.is_bound and not self.errors
  File "C:\Users\Samo\AppData\Local\Programs\Python\Python35\lib\site-packages\django\forms\forms.py", line 153, in errors
    self.full_clean()
  File "C:\Users\Samo\AppData\Local\Programs\Python\Python35\lib\site-packages\django\forms\forms.py", line 362, in full_clean
    self._clean_fields()
  File "C:\Users\Samo\AppData\Local\Programs\Python\Python35\lib\site-packages\django\forms\forms.py", line 383, in _clean_fields
    value = getattr(self, 'clean_%s' % name)()
  File "C:\Users\Samo\Desktop\projekt-tomo\projekt-tomo\web\users\admin.py", line 18, in clean_username
    raise forms.ValidationError(self.error_messages['duplicate_username'])
KeyError: 'duplicate_username'
Internal Server Error: /admin/users/user/add/
Traceback (most recent call last):
  File "C:\Users\Samo\AppData\Local\Programs\Python\Python35\lib\site-packages\django\core\handlers\base.py", line 149, in get_response
    response = self.process_exception_by_middleware(e, request)
  File "C:\Users\Samo\AppData\Local\Programs\Python\Python35\lib\site-packages\django\core\handlers\base.py", line 147, in get_response
    response = wrapped_callback(request, *callback_args, **callback_kwargs)
  File "C:\Users\Samo\AppData\Local\Programs\Python\Python35\lib\site-packages\django\contrib\admin\options.py", line 541, in wrapper
    return self.admin_site.admin_view(view)(*args, **kwargs)
  File "C:\Users\Samo\AppData\Local\Programs\Python\Python35\lib\site-packages\django\utils\decorators.py", line 149, in _wrapped_view
    response = view_func(request, *args, **kwargs)
  File "C:\Users\Samo\AppData\Local\Programs\Python\Python35\lib\site-packages\django\views\decorators\cache.py", line 57, in _wrapped_view_func
    response = view_func(request, *args, **kwargs)
  File "C:\Users\Samo\AppData\Local\Programs\Python\Python35\lib\site-packages\django\contrib\admin\sites.py", line 244, in inner
    return view(request, *args, **kwargs)
  File "C:\Users\Samo\AppData\Local\Programs\Python\Python35\lib\site-packages\django\utils\decorators.py", line 67, in _wrapper
    return bound_func(*args, **kwargs)
  File "C:\Users\Samo\AppData\Local\Programs\Python\Python35\lib\site-packages\django\views\decorators\debug.py", line 76, in sensitive_post_parameters_wrapper
    return view(request, *args, **kwargs)
  File "C:\Users\Samo\AppData\Local\Programs\Python\Python35\lib\site-packages\django\utils\decorators.py", line 63, in bound_func
    return func.__get__(self, type(self))(*args2, **kwargs2)
  File "C:\Users\Samo\AppData\Local\Programs\Python\Python35\lib\site-packages\django\utils\decorators.py", line 67, in _wrapper
    return bound_func(*args, **kwargs)
  File "C:\Users\Samo\AppData\Local\Programs\Python\Python35\lib\site-packages\django\utils\decorators.py", line 149, in _wrapped_view
    response = view_func(request, *args, **kwargs)
  File "C:\Users\Samo\AppData\Local\Programs\Python\Python35\lib\site-packages\django\utils\decorators.py", line 63, in bound_func
    return func.__get__(self, type(self))(*args2, **kwargs2)
  File "C:\Users\Samo\AppData\Local\Programs\Python\Python35\lib\contextlib.py", line 30, in inner
    return func(*args, **kwds)
  File "C:\Users\Samo\AppData\Local\Programs\Python\Python35\lib\site-packages\django\contrib\auth\admin.py", line 128, in add_view
    extra_context)
  File "C:\Users\Samo\AppData\Local\Programs\Python\Python35\lib\site-packages\django\contrib\admin\options.py", line 1437, in add_view
    return self.changeform_view(request, None, form_url, extra_context)
  File "C:\Users\Samo\AppData\Local\Programs\Python\Python35\lib\site-packages\django\utils\decorators.py", line 67, in _wrapper
    return bound_func(*args, **kwargs)
  File "C:\Users\Samo\AppData\Local\Programs\Python\Python35\lib\site-packages\django\utils\decorators.py", line 149, in _wrapped_view
    response = view_func(request, *args, **kwargs)
  File "C:\Users\Samo\AppData\Local\Programs\Python\Python35\lib\site-packages\django\utils\decorators.py", line 63, in bound_func
    return func.__get__(self, type(self))(*args2, **kwargs2)
  File "C:\Users\Samo\AppData\Local\Programs\Python\Python35\lib\contextlib.py", line 30, in inner
    return func(*args, **kwds)
  File "C:\Users\Samo\AppData\Local\Programs\Python\Python35\lib\site-packages\django\contrib\admin\options.py", line 1370, in changeform_view
    if form.is_valid():
  File "C:\Users\Samo\AppData\Local\Programs\Python\Python35\lib\site-packages\django\forms\forms.py", line 161, in is_valid
    return self.is_bound and not self.errors
  File "C:\Users\Samo\AppData\Local\Programs\Python\Python35\lib\site-packages\django\forms\forms.py", line 153, in errors
    self.full_clean()
  File "C:\Users\Samo\AppData\Local\Programs\Python\Python35\lib\site-packages\django\forms\forms.py", line 362, in full_clean
    self._clean_fields()
  File "C:\Users\Samo\AppData\Local\Programs\Python\Python35\lib\site-packages\django\forms\forms.py", line 383, in _clean_fields
    value = getattr(self, 'clean_%s' % name)()
  File "C:\Users\Samo\Desktop\projekt-tomo\projekt-tomo\web\users\admin.py", line 18, in clean_username
    raise forms.ValidationError(self.error_messages['duplicate_username'])
KeyError: 'duplicate_username'
Internal Server Error: /admin/users/user/add/
Traceback (most recent call last):
  File "C:\Users\Samo\AppData\Local\Programs\Python\Python35\lib\site-packages\django\core\handlers\base.py", line 149, in get_response
    response = self.process_exception_by_middleware(e, request)
  File "C:\Users\Samo\AppData\Local\Programs\Python\Python35\lib\site-packages\django\core\handlers\base.py", line 147, in get_response
    response = wrapped_callback(request, *callback_args, **callback_kwargs)
  File "C:\Users\Samo\AppData\Local\Programs\Python\Python35\lib\site-packages\django\contrib\admin\options.py", line 541, in wrapper
    return self.admin_site.admin_view(view)(*args, **kwargs)
  File "C:\Users\Samo\AppData\Local\Programs\Python\Python35\lib\site-packages\django\utils\decorators.py", line 149, in _wrapped_view
    response = view_func(request, *args, **kwargs)
  File "C:\Users\Samo\AppData\Local\Programs\Python\Python35\lib\site-packages\django\views\decorators\cache.py", line 57, in _wrapped_view_func
    response = view_func(request, *args, **kwargs)
  File "C:\Users\Samo\AppData\Local\Programs\Python\Python35\lib\site-packages\django\contrib\admin\sites.py", line 244, in inner
    return view(request, *args, **kwargs)
  File "C:\Users\Samo\AppData\Local\Programs\Python\Python35\lib\site-packages\django\utils\decorators.py", line 67, in _wrapper
    return bound_func(*args, **kwargs)
  File "C:\Users\Samo\AppData\Local\Programs\Python\Python35\lib\site-packages\django\views\decorators\debug.py", line 76, in sensitive_post_parameters_wrapper
    return view(request, *args, **kwargs)
  File "C:\Users\Samo\AppData\Local\Programs\Python\Python35\lib\site-packages\django\utils\decorators.py", line 63, in bound_func
    return func.__get__(self, type(self))(*args2, **kwargs2)
  File "C:\Users\Samo\AppData\Local\Programs\Python\Python35\lib\site-packages\django\utils\decorators.py", line 67, in _wrapper
    return bound_func(*args, **kwargs)
  File "C:\Users\Samo\AppData\Local\Programs\Python\Python35\lib\site-packages\django\utils\decorators.py", line 149, in _wrapped_view
    response = view_func(request, *args, **kwargs)
  File "C:\Users\Samo\AppData\Local\Programs\Python\Python35\lib\site-packages\django\utils\decorators.py", line 63, in bound_func
    return func.__get__(self, type(self))(*args2, **kwargs2)
  File "C:\Users\Samo\AppData\Local\Programs\Python\Python35\lib\contextlib.py", line 30, in inner
    return func(*args, **kwds)
  File "C:\Users\Samo\AppData\Local\Programs\Python\Python35\lib\site-packages\django\contrib\auth\admin.py", line 128, in add_view
    extra_context)
  File "C:\Users\Samo\AppData\Local\Programs\Python\Python35\lib\site-packages\django\contrib\admin\options.py", line 1437, in add_view
    return self.changeform_view(request, None, form_url, extra_context)
  File "C:\Users\Samo\AppData\Local\Programs\Python\Python35\lib\site-packages\django\utils\decorators.py", line 67, in _wrapper
    return bound_func(*args, **kwargs)
  File "C:\Users\Samo\AppData\Local\Programs\Python\Python35\lib\site-packages\django\utils\decorators.py", line 149, in _wrapped_view
    response = view_func(request, *args, **kwargs)
  File "C:\Users\Samo\AppData\Local\Programs\Python\Python35\lib\site-packages\django\utils\decorators.py", line 63, in bound_func
    return func.__get__(self, type(self))(*args2, **kwargs2)
  File "C:\Users\Samo\AppData\Local\Programs\Python\Python35\lib\contextlib.py", line 30, in inner
    return func(*args, **kwds)
  File "C:\Users\Samo\AppData\Local\Programs\Python\Python35\lib\site-packages\django\contrib\admin\options.py", line 1370, in changeform_view
    if form.is_valid():
  File "C:\Users\Samo\AppData\Local\Programs\Python\Python35\lib\site-packages\django\forms\forms.py", line 161, in is_valid
    return self.is_bound and not self.errors
  File "C:\Users\Samo\AppData\Local\Programs\Python\Python35\lib\site-packages\django\forms\forms.py", line 153, in errors
    self.full_clean()
  File "C:\Users\Samo\AppData\Local\Programs\Python\Python35\lib\site-packages\django\forms\forms.py", line 362, in full_clean
    self._clean_fields()
  File "C:\Users\Samo\AppData\Local\Programs\Python\Python35\lib\site-packages\django\forms\forms.py", line 383, in _clean_fields
    value = getattr(self, 'clean_%s' % name)()
  File "C:\Users\Samo\Desktop\projekt-tomo\projekt-tomo\web\users\admin.py", line 18, in clean_username
    raise forms.ValidationError(self.error_messages['duplicate_username'])
KeyError: 'duplicate_username'
Internal Server Error: /admin/users/user/add/
Traceback (most recent call last):
  File "C:\Users\Samo\AppData\Local\Programs\Python\Python35\lib\site-packages\django\core\handlers\base.py", line 149, in get_response
    response = self.process_exception_by_middleware(e, request)
  File "C:\Users\Samo\AppData\Local\Programs\Python\Python35\lib\site-packages\django\core\handlers\base.py", line 147, in get_response
    response = wrapped_callback(request, *callback_args, **callback_kwargs)
  File "C:\Users\Samo\AppData\Local\Programs\Python\Python35\lib\site-packages\django\contrib\admin\options.py", line 541, in wrapper
    return self.admin_site.admin_view(view)(*args, **kwargs)
  File "C:\Users\Samo\AppData\Local\Programs\Python\Python35\lib\site-packages\django\utils\decorators.py", line 149, in _wrapped_view
    response = view_func(request, *args, **kwargs)
  File "C:\Users\Samo\AppData\Local\Programs\Python\Python35\lib\site-packages\django\views\decorators\cache.py", line 57, in _wrapped_view_func
    response = view_func(request, *args, **kwargs)
  File "C:\Users\Samo\AppData\Local\Programs\Python\Python35\lib\site-packages\django\contrib\admin\sites.py", line 244, in inner
    return view(request, *args, **kwargs)
  File "C:\Users\Samo\AppData\Local\Programs\Python\Python35\lib\site-packages\django\utils\decorators.py", line 67, in _wrapper
    return bound_func(*args, **kwargs)
  File "C:\Users\Samo\AppData\Local\Programs\Python\Python35\lib\site-packages\django\views\decorators\debug.py", line 76, in sensitive_post_parameters_wrapper
    return view(request, *args, **kwargs)
  File "C:\Users\Samo\AppData\Local\Programs\Python\Python35\lib\site-packages\django\utils\decorators.py", line 63, in bound_func
    return func.__get__(self, type(self))(*args2, **kwargs2)
  File "C:\Users\Samo\AppData\Local\Programs\Python\Python35\lib\site-packages\django\utils\decorators.py", line 67, in _wrapper
    return bound_func(*args, **kwargs)
  File "C:\Users\Samo\AppData\Local\Programs\Python\Python35\lib\site-packages\django\utils\decorators.py", line 149, in _wrapped_view
    response = view_func(request, *args, **kwargs)
  File "C:\Users\Samo\AppData\Local\Programs\Python\Python35\lib\site-packages\django\utils\decorators.py", line 63, in bound_func
    return func.__get__(self, type(self))(*args2, **kwargs2)
  File "C:\Users\Samo\AppData\Local\Programs\Python\Python35\lib\contextlib.py", line 30, in inner
    return func(*args, **kwds)
  File "C:\Users\Samo\AppData\Local\Programs\Python\Python35\lib\site-packages\django\contrib\auth\admin.py", line 128, in add_view
    extra_context)
  File "C:\Users\Samo\AppData\Local\Programs\Python\Python35\lib\site-packages\django\contrib\admin\options.py", line 1437, in add_view
    return self.changeform_view(request, None, form_url, extra_context)
  File "C:\Users\Samo\AppData\Local\Programs\Python\Python35\lib\site-packages\django\utils\decorators.py", line 67, in _wrapper
    return bound_func(*args, **kwargs)
  File "C:\Users\Samo\AppData\Local\Programs\Python\Python35\lib\site-packages\django\utils\decorators.py", line 149, in _wrapped_view
    response = view_func(request, *args, **kwargs)
  File "C:\Users\Samo\AppData\Local\Programs\Python\Python35\lib\site-packages\django\utils\decorators.py", line 63, in bound_func
    return func.__get__(self, type(self))(*args2, **kwargs2)
  File "C:\Users\Samo\AppData\Local\Programs\Python\Python35\lib\contextlib.py", line 30, in inner
    return func(*args, **kwds)
  File "C:\Users\Samo\AppData\Local\Programs\Python\Python35\lib\site-packages\django\contrib\admin\options.py", line 1370, in changeform_view
    if form.is_valid():
  File "C:\Users\Samo\AppData\Local\Programs\Python\Python35\lib\site-packages\django\forms\forms.py", line 161, in is_valid
    return self.is_bound and not self.errors
  File "C:\Users\Samo\AppData\Local\Programs\Python\Python35\lib\site-packages\django\forms\forms.py", line 153, in errors
    self.full_clean()
  File "C:\Users\Samo\AppData\Local\Programs\Python\Python35\lib\site-packages\django\forms\forms.py", line 362, in full_clean
    self._clean_fields()
  File "C:\Users\Samo\AppData\Local\Programs\Python\Python35\lib\site-packages\django\forms\forms.py", line 383, in _clean_fields
    value = getattr(self, 'clean_%s' % name)()
  File "C:\Users\Samo\Desktop\projekt-tomo\projekt-tomo\web\users\admin.py", line 18, in clean_username
    raise forms.ValidationError(self.error_messages['duplicate_username'])
KeyError: 'duplicate_username'
Internal Server Error: /admin/users/user/add/
Traceback (most recent call last):
  File "C:\Users\Samo\AppData\Local\Programs\Python\Python35\lib\site-packages\django\core\handlers\base.py", line 149, in get_response
    response = self.process_exception_by_middleware(e, request)
  File "C:\Users\Samo\AppData\Local\Programs\Python\Python35\lib\site-packages\django\core\handlers\base.py", line 147, in get_response
    response = wrapped_callback(request, *callback_args, **callback_kwargs)
  File "C:\Users\Samo\AppData\Local\Programs\Python\Python35\lib\site-packages\django\contrib\admin\options.py", line 541, in wrapper
    return self.admin_site.admin_view(view)(*args, **kwargs)
  File "C:\Users\Samo\AppData\Local\Programs\Python\Python35\lib\site-packages\django\utils\decorators.py", line 149, in _wrapped_view
    response = view_func(request, *args, **kwargs)
  File "C:\Users\Samo\AppData\Local\Programs\Python\Python35\lib\site-packages\django\views\decorators\cache.py", line 57, in _wrapped_view_func
    response = view_func(request, *args, **kwargs)
  File "C:\Users\Samo\AppData\Local\Programs\Python\Python35\lib\site-packages\django\contrib\admin\sites.py", line 244, in inner
    return view(request, *args, **kwargs)
  File "C:\Users\Samo\AppData\Local\Programs\Python\Python35\lib\site-packages\django\utils\decorators.py", line 67, in _wrapper
    return bound_func(*args, **kwargs)
  File "C:\Users\Samo\AppData\Local\Programs\Python\Python35\lib\site-packages\django\views\decorators\debug.py", line 76, in sensitive_post_parameters_wrapper
    return view(request, *args, **kwargs)
  File "C:\Users\Samo\AppData\Local\Programs\Python\Python35\lib\site-packages\django\utils\decorators.py", line 63, in bound_func
    return func.__get__(self, type(self))(*args2, **kwargs2)
  File "C:\Users\Samo\AppData\Local\Programs\Python\Python35\lib\site-packages\django\utils\decorators.py", line 67, in _wrapper
    return bound_func(*args, **kwargs)
  File "C:\Users\Samo\AppData\Local\Programs\Python\Python35\lib\site-packages\django\utils\decorators.py", line 149, in _wrapped_view
    response = view_func(request, *args, **kwargs)
  File "C:\Users\Samo\AppData\Local\Programs\Python\Python35\lib\site-packages\django\utils\decorators.py", line 63, in bound_func
    return func.__get__(self, type(self))(*args2, **kwargs2)
  File "C:\Users\Samo\AppData\Local\Programs\Python\Python35\lib\contextlib.py", line 30, in inner
    return func(*args, **kwds)
  File "C:\Users\Samo\AppData\Local\Programs\Python\Python35\lib\site-packages\django\contrib\auth\admin.py", line 128, in add_view
    extra_context)
  File "C:\Users\Samo\AppData\Local\Programs\Python\Python35\lib\site-packages\django\contrib\admin\options.py", line 1437, in add_view
    return self.changeform_view(request, None, form_url, extra_context)
  File "C:\Users\Samo\AppData\Local\Programs\Python\Python35\lib\site-packages\django\utils\decorators.py", line 67, in _wrapper
    return bound_func(*args, **kwargs)
  File "C:\Users\Samo\AppData\Local\Programs\Python\Python35\lib\site-packages\django\utils\decorators.py", line 149, in _wrapped_view
    response = view_func(request, *args, **kwargs)
  File "C:\Users\Samo\AppData\Local\Programs\Python\Python35\lib\site-packages\django\utils\decorators.py", line 63, in bound_func
    return func.__get__(self, type(self))(*args2, **kwargs2)
  File "C:\Users\Samo\AppData\Local\Programs\Python\Python35\lib\contextlib.py", line 30, in inner
    return func(*args, **kwds)
  File "C:\Users\Samo\AppData\Local\Programs\Python\Python35\lib\site-packages\django\contrib\admin\options.py", line 1370, in changeform_view
    if form.is_valid():
  File "C:\Users\Samo\AppData\Local\Programs\Python\Python35\lib\site-packages\django\forms\forms.py", line 161, in is_valid
    return self.is_bound and not self.errors
  File "C:\Users\Samo\AppData\Local\Programs\Python\Python35\lib\site-packages\django\forms\forms.py", line 153, in errors
    self.full_clean()
  File "C:\Users\Samo\AppData\Local\Programs\Python\Python35\lib\site-packages\django\forms\forms.py", line 362, in full_clean
    self._clean_fields()
  File "C:\Users\Samo\AppData\Local\Programs\Python\Python35\lib\site-packages\django\forms\forms.py", line 383, in _clean_fields
    value = getattr(self, 'clean_%s' % name)()
  File "C:\Users\Samo\Desktop\projekt-tomo\projekt-tomo\web\users\admin.py", line 18, in clean_username
    raise forms.ValidationError(self.error_messages['duplicate_username'])
KeyError: 'duplicate_username'
Internal Server Error: /admin/users/user/add/
Traceback (most recent call last):
  File "C:\Users\Samo\AppData\Local\Programs\Python\Python35\lib\site-packages\django\core\handlers\base.py", line 149, in get_response
    response = self.process_exception_by_middleware(e, request)
  File "C:\Users\Samo\AppData\Local\Programs\Python\Python35\lib\site-packages\django\core\handlers\base.py", line 147, in get_response
    response = wrapped_callback(request, *callback_args, **callback_kwargs)
  File "C:\Users\Samo\AppData\Local\Programs\Python\Python35\lib\site-packages\django\contrib\admin\options.py", line 541, in wrapper
    return self.admin_site.admin_view(view)(*args, **kwargs)
  File "C:\Users\Samo\AppData\Local\Programs\Python\Python35\lib\site-packages\django\utils\decorators.py", line 149, in _wrapped_view
    response = view_func(request, *args, **kwargs)
  File "C:\Users\Samo\AppData\Local\Programs\Python\Python35\lib\site-packages\django\views\decorators\cache.py", line 57, in _wrapped_view_func
    response = view_func(request, *args, **kwargs)
  File "C:\Users\Samo\AppData\Local\Programs\Python\Python35\lib\site-packages\django\contrib\admin\sites.py", line 244, in inner
    return view(request, *args, **kwargs)
  File "C:\Users\Samo\AppData\Local\Programs\Python\Python35\lib\site-packages\django\utils\decorators.py", line 67, in _wrapper
    return bound_func(*args, **kwargs)
  File "C:\Users\Samo\AppData\Local\Programs\Python\Python35\lib\site-packages\django\views\decorators\debug.py", line 76, in sensitive_post_parameters_wrapper
    return view(request, *args, **kwargs)
  File "C:\Users\Samo\AppData\Local\Programs\Python\Python35\lib\site-packages\django\utils\decorators.py", line 63, in bound_func
    return func.__get__(self, type(self))(*args2, **kwargs2)
  File "C:\Users\Samo\AppData\Local\Programs\Python\Python35\lib\site-packages\django\utils\decorators.py", line 67, in _wrapper
    return bound_func(*args, **kwargs)
  File "C:\Users\Samo\AppData\Local\Programs\Python\Python35\lib\site-packages\django\utils\decorators.py", line 149, in _wrapped_view
    response = view_func(request, *args, **kwargs)
  File "C:\Users\Samo\AppData\Local\Programs\Python\Python35\lib\site-packages\django\utils\decorators.py", line 63, in bound_func
    return func.__get__(self, type(self))(*args2, **kwargs2)
  File "C:\Users\Samo\AppData\Local\Programs\Python\Python35\lib\contextlib.py", line 30, in inner
    return func(*args, **kwds)
  File "C:\Users\Samo\AppData\Local\Programs\Python\Python35\lib\site-packages\django\contrib\auth\admin.py", line 128, in add_view
    extra_context)
  File "C:\Users\Samo\AppData\Local\Programs\Python\Python35\lib\site-packages\django\contrib\admin\options.py", line 1437, in add_view
    return self.changeform_view(request, None, form_url, extra_context)
  File "C:\Users\Samo\AppData\Local\Programs\Python\Python35\lib\site-packages\django\utils\decorators.py", line 67, in _wrapper
    return bound_func(*args, **kwargs)
  File "C:\Users\Samo\AppData\Local\Programs\Python\Python35\lib\site-packages\django\utils\decorators.py", line 149, in _wrapped_view
    response = view_func(request, *args, **kwargs)
  File "C:\Users\Samo\AppData\Local\Programs\Python\Python35\lib\site-packages\django\utils\decorators.py", line 63, in bound_func
    return func.__get__(self, type(self))(*args2, **kwargs2)
  File "C:\Users\Samo\AppData\Local\Programs\Python\Python35\lib\contextlib.py", line 30, in inner
    return func(*args, **kwds)
  File "C:\Users\Samo\AppData\Local\Programs\Python\Python35\lib\site-packages\django\contrib\admin\options.py", line 1370, in changeform_view
    if form.is_valid():
  File "C:\Users\Samo\AppData\Local\Programs\Python\Python35\lib\site-packages\django\forms\forms.py", line 161, in is_valid
    return self.is_bound and not self.errors
  File "C:\Users\Samo\AppData\Local\Programs\Python\Python35\lib\site-packages\django\forms\forms.py", line 153, in errors
    self.full_clean()
  File "C:\Users\Samo\AppData\Local\Programs\Python\Python35\lib\site-packages\django\forms\forms.py", line 362, in full_clean
    self._clean_fields()
  File "C:\Users\Samo\AppData\Local\Programs\Python\Python35\lib\site-packages\django\forms\forms.py", line 383, in _clean_fields
    value = getattr(self, 'clean_%s' % name)()
  File "C:\Users\Samo\Desktop\projekt-tomo\projekt-tomo\web\users\admin.py", line 18, in clean_username
    raise forms.ValidationError(self.error_messages['duplicate_username'])
KeyError: 'duplicate_username'
Internal Server Error: /admin/users/user/add/
Traceback (most recent call last):
  File "C:\Users\Samo\AppData\Local\Programs\Python\Python35\lib\site-packages\django\core\handlers\base.py", line 149, in get_response
    response = self.process_exception_by_middleware(e, request)
  File "C:\Users\Samo\AppData\Local\Programs\Python\Python35\lib\site-packages\django\core\handlers\base.py", line 147, in get_response
    response = wrapped_callback(request, *callback_args, **callback_kwargs)
  File "C:\Users\Samo\AppData\Local\Programs\Python\Python35\lib\site-packages\django\contrib\admin\options.py", line 541, in wrapper
    return self.admin_site.admin_view(view)(*args, **kwargs)
  File "C:\Users\Samo\AppData\Local\Programs\Python\Python35\lib\site-packages\django\utils\decorators.py", line 149, in _wrapped_view
    response = view_func(request, *args, **kwargs)
  File "C:\Users\Samo\AppData\Local\Programs\Python\Python35\lib\site-packages\django\views\decorators\cache.py", line 57, in _wrapped_view_func
    response = view_func(request, *args, **kwargs)
  File "C:\Users\Samo\AppData\Local\Programs\Python\Python35\lib\site-packages\django\contrib\admin\sites.py", line 244, in inner
    return view(request, *args, **kwargs)
  File "C:\Users\Samo\AppData\Local\Programs\Python\Python35\lib\site-packages\django\utils\decorators.py", line 67, in _wrapper
    return bound_func(*args, **kwargs)
  File "C:\Users\Samo\AppData\Local\Programs\Python\Python35\lib\site-packages\django\views\decorators\debug.py", line 76, in sensitive_post_parameters_wrapper
    return view(request, *args, **kwargs)
  File "C:\Users\Samo\AppData\Local\Programs\Python\Python35\lib\site-packages\django\utils\decorators.py", line 63, in bound_func
    return func.__get__(self, type(self))(*args2, **kwargs2)
  File "C:\Users\Samo\AppData\Local\Programs\Python\Python35\lib\site-packages\django\utils\decorators.py", line 67, in _wrapper
    return bound_func(*args, **kwargs)
  File "C:\Users\Samo\AppData\Local\Programs\Python\Python35\lib\site-packages\django\utils\decorators.py", line 149, in _wrapped_view
    response = view_func(request, *args, **kwargs)
  File "C:\Users\Samo\AppData\Local\Programs\Python\Python35\lib\site-packages\django\utils\decorators.py", line 63, in bound_func
    return func.__get__(self, type(self))(*args2, **kwargs2)
  File "C:\Users\Samo\AppData\Local\Programs\Python\Python35\lib\contextlib.py", line 30, in inner
    return func(*args, **kwds)
  File "C:\Users\Samo\AppData\Local\Programs\Python\Python35\lib\site-packages\django\contrib\auth\admin.py", line 128, in add_view
    extra_context)
  File "C:\Users\Samo\AppData\Local\Programs\Python\Python35\lib\site-packages\django\contrib\admin\options.py", line 1437, in add_view
    return self.changeform_view(request, None, form_url, extra_context)
  File "C:\Users\Samo\AppData\Local\Programs\Python\Python35\lib\site-packages\django\utils\decorators.py", line 67, in _wrapper
    return bound_func(*args, **kwargs)
  File "C:\Users\Samo\AppData\Local\Programs\Python\Python35\lib\site-packages\django\utils\decorators.py", line 149, in _wrapped_view
    response = view_func(request, *args, **kwargs)
  File "C:\Users\Samo\AppData\Local\Programs\Python\Python35\lib\site-packages\django\utils\decorators.py", line 63, in bound_func
    return func.__get__(self, type(self))(*args2, **kwargs2)
  File "C:\Users\Samo\AppData\Local\Programs\Python\Python35\lib\contextlib.py", line 30, in inner
    return func(*args, **kwds)
  File "C:\Users\Samo\AppData\Local\Programs\Python\Python35\lib\site-packages\django\contrib\admin\options.py", line 1370, in changeform_view
    if form.is_valid():
  File "C:\Users\Samo\AppData\Local\Programs\Python\Python35\lib\site-packages\django\forms\forms.py", line 161, in is_valid
    return self.is_bound and not self.errors
  File "C:\Users\Samo\AppData\Local\Programs\Python\Python35\lib\site-packages\django\forms\forms.py", line 153, in errors
    self.full_clean()
  File "C:\Users\Samo\AppData\Local\Programs\Python\Python35\lib\site-packages\django\forms\forms.py", line 362, in full_clean
    self._clean_fields()
  File "C:\Users\Samo\AppData\Local\Programs\Python\Python35\lib\site-packages\django\forms\forms.py", line 383, in _clean_fields
    value = getattr(self, 'clean_%s' % name)()
  File "C:\Users\Samo\Desktop\projekt-tomo\projekt-tomo\web\users\admin.py", line 18, in clean_username
    raise forms.ValidationError(self.error_messages['duplicate_username'])
KeyError: 'duplicate_username'
Internal Server Error: /admin/users/user/add/
Traceback (most recent call last):
  File "C:\Users\Samo\AppData\Local\Programs\Python\Python35\lib\site-packages\django\core\handlers\base.py", line 149, in get_response
    response = self.process_exception_by_middleware(e, request)
  File "C:\Users\Samo\AppData\Local\Programs\Python\Python35\lib\site-packages\django\core\handlers\base.py", line 147, in get_response
    response = wrapped_callback(request, *callback_args, **callback_kwargs)
  File "C:\Users\Samo\AppData\Local\Programs\Python\Python35\lib\site-packages\django\contrib\admin\options.py", line 541, in wrapper
    return self.admin_site.admin_view(view)(*args, **kwargs)
  File "C:\Users\Samo\AppData\Local\Programs\Python\Python35\lib\site-packages\django\utils\decorators.py", line 149, in _wrapped_view
    response = view_func(request, *args, **kwargs)
  File "C:\Users\Samo\AppData\Local\Programs\Python\Python35\lib\site-packages\django\views\decorators\cache.py", line 57, in _wrapped_view_func
    response = view_func(request, *args, **kwargs)
  File "C:\Users\Samo\AppData\Local\Programs\Python\Python35\lib\site-packages\django\contrib\admin\sites.py", line 244, in inner
    return view(request, *args, **kwargs)
  File "C:\Users\Samo\AppData\Local\Programs\Python\Python35\lib\site-packages\django\utils\decorators.py", line 67, in _wrapper
    return bound_func(*args, **kwargs)
  File "C:\Users\Samo\AppData\Local\Programs\Python\Python35\lib\site-packages\django\views\decorators\debug.py", line 76, in sensitive_post_parameters_wrapper
    return view(request, *args, **kwargs)
  File "C:\Users\Samo\AppData\Local\Programs\Python\Python35\lib\site-packages\django\utils\decorators.py", line 63, in bound_func
    return func.__get__(self, type(self))(*args2, **kwargs2)
  File "C:\Users\Samo\AppData\Local\Programs\Python\Python35\lib\site-packages\django\utils\decorators.py", line 67, in _wrapper
    return bound_func(*args, **kwargs)
  File "C:\Users\Samo\AppData\Local\Programs\Python\Python35\lib\site-packages\django\utils\decorators.py", line 149, in _wrapped_view
    response = view_func(request, *args, **kwargs)
  File "C:\Users\Samo\AppData\Local\Programs\Python\Python35\lib\site-packages\django\utils\decorators.py", line 63, in bound_func
    return func.__get__(self, type(self))(*args2, **kwargs2)
  File "C:\Users\Samo\AppData\Local\Programs\Python\Python35\lib\contextlib.py", line 30, in inner
    return func(*args, **kwds)
  File "C:\Users\Samo\AppData\Local\Programs\Python\Python35\lib\site-packages\django\contrib\auth\admin.py", line 128, in add_view
    extra_context)
  File "C:\Users\Samo\AppData\Local\Programs\Python\Python35\lib\site-packages\django\contrib\admin\options.py", line 1437, in add_view
    return self.changeform_view(request, None, form_url, extra_context)
  File "C:\Users\Samo\AppData\Local\Programs\Python\Python35\lib\site-packages\django\utils\decorators.py", line 67, in _wrapper
    return bound_func(*args, **kwargs)
  File "C:\Users\Samo\AppData\Local\Programs\Python\Python35\lib\site-packages\django\utils\decorators.py", line 149, in _wrapped_view
    response = view_func(request, *args, **kwargs)
  File "C:\Users\Samo\AppData\Local\Programs\Python\Python35\lib\site-packages\django\utils\decorators.py", line 63, in bound_func
    return func.__get__(self, type(self))(*args2, **kwargs2)
  File "C:\Users\Samo\AppData\Local\Programs\Python\Python35\lib\contextlib.py", line 30, in inner
    return func(*args, **kwds)
  File "C:\Users\Samo\AppData\Local\Programs\Python\Python35\lib\site-packages\django\contrib\admin\options.py", line 1370, in changeform_view
    if form.is_valid():
  File "C:\Users\Samo\AppData\Local\Programs\Python\Python35\lib\site-packages\django\forms\forms.py", line 161, in is_valid
    return self.is_bound and not self.errors
  File "C:\Users\Samo\AppData\Local\Programs\Python\Python35\lib\site-packages\django\forms\forms.py", line 153, in errors
    self.full_clean()
  File "C:\Users\Samo\AppData\Local\Programs\Python\Python35\lib\site-packages\django\forms\forms.py", line 362, in full_clean
    self._clean_fields()
  File "C:\Users\Samo\AppData\Local\Programs\Python\Python35\lib\site-packages\django\forms\forms.py", line 383, in _clean_fields
    value = getattr(self, 'clean_%s' % name)()
  File "C:\Users\Samo\Desktop\projekt-tomo\projekt-tomo\web\users\admin.py", line 18, in clean_username
    raise forms.ValidationError(self.error_messages['duplicate_username'])
KeyError: 'duplicate_username'
Not Found: /favicon.ico
