Not Found: /graf
Not Found: /tomo_statistics/graf
Internal Server Error: /tomo_statistics/graf_test/2/
Traceback (most recent call last):
  File "C:\Users\Samo\AppData\Local\Programs\Python\Python35\lib\site-packages\django\core\handlers\base.py", line 149, in get_response
    response = self.process_exception_by_middleware(e, request)
  File "C:\Users\Samo\AppData\Local\Programs\Python\Python35\lib\site-packages\django\core\handlers\base.py", line 147, in get_response
    response = wrapped_callback(request, *callback_args, **callback_kwargs)
  File "C:\Users\Samo\Desktop\projekt-tomo\projekt-tomo\web\tomo_statistics\views.py", line 15, in graph
    response = JsonResponse(course.json_za_graf())
  File "C:\Users\Samo\AppData\Local\Programs\Python\Python35\lib\site-packages\django\http\response.py", line 500, in __init__
    raise TypeError('In order to allow non-dict objects to be '
TypeError: In order to allow non-dict objects to be serialized set the safe parameter to False
Internal Server Error: /tomo_statistics/graf_test/2/
Traceback (most recent call last):
  File "C:\Users\Samo\AppData\Local\Programs\Python\Python35\lib\site-packages\django\core\handlers\base.py", line 149, in get_response
    response = self.process_exception_by_middleware(e, request)
  File "C:\Users\Samo\AppData\Local\Programs\Python\Python35\lib\site-packages\django\core\handlers\base.py", line 147, in get_response
    response = wrapped_callback(request, *callback_args, **callback_kwargs)
  File "C:\Users\Samo\Desktop\projekt-tomo\projekt-tomo\web\tomo_statistics\views.py", line 15, in graph
    response = JsonResponse(course.json_za_graf())
  File "C:\Users\Samo\AppData\Local\Programs\Python\Python35\lib\site-packages\django\http\response.py", line 500, in __init__
    raise TypeError('In order to allow non-dict objects to be '
TypeError: In order to allow non-dict objects to be serialized set the safe parameter to False
Internal Server Error: /tomo_statistics/graf_test/2/
Traceback (most recent call last):
  File "C:\Users\Samo\AppData\Local\Programs\Python\Python35\lib\site-packages\django\core\handlers\base.py", line 149, in get_response
    response = self.process_exception_by_middleware(e, request)
  File "C:\Users\Samo\AppData\Local\Programs\Python\Python35\lib\site-packages\django\core\handlers\base.py", line 147, in get_response
    response = wrapped_callback(request, *callback_args, **callback_kwargs)
  File "C:\Users\Samo\Desktop\projekt-tomo\projekt-tomo\web\tomo_statistics\views.py", line 15, in graph
    response = JsonResponse(course.json_za_graf())
  File "C:\Users\Samo\AppData\Local\Programs\Python\Python35\lib\site-packages\django\http\response.py", line 500, in __init__
    raise TypeError('In order to allow non-dict objects to be '
TypeError: In order to allow non-dict objects to be serialized set the safe parameter to False
Internal Server Error: /tomo_statistics/graf_test/2/
Traceback (most recent call last):
  File "C:\Users\Samo\AppData\Local\Programs\Python\Python35\lib\site-packages\django\core\handlers\base.py", line 149, in get_response
    response = self.process_exception_by_middleware(e, request)
  File "C:\Users\Samo\AppData\Local\Programs\Python\Python35\lib\site-packages\django\core\handlers\base.py", line 147, in get_response
    response = wrapped_callback(request, *callback_args, **callback_kwargs)
  File "C:\Users\Samo\Desktop\projekt-tomo\projekt-tomo\web\tomo_statistics\views.py", line 16, in graph
    return render(request, 'tomo_statistics/graf.html', course.json_za_graf())
  File "C:\Users\Samo\AppData\Local\Programs\Python\Python35\lib\site-packages\django\shortcuts.py", line 67, in render
    template_name, context, request=request, using=using)
  File "C:\Users\Samo\AppData\Local\Programs\Python\Python35\lib\site-packages\django\template\loader.py", line 97, in render_to_string
    return template.render(context, request)
  File "C:\Users\Samo\AppData\Local\Programs\Python\Python35\lib\site-packages\django\template\backends\django.py", line 92, in render
    context = make_context(context, request)
  File "C:\Users\Samo\AppData\Local\Programs\Python\Python35\lib\site-packages\django\template\context.py", line 291, in make_context
    context.push(original_context)
  File "C:\Users\Samo\AppData\Local\Programs\Python\Python35\lib\site-packages\django\template\context.py", line 61, in push
    return ContextDict(self, *dicts, **kwargs)
  File "C:\Users\Samo\AppData\Local\Programs\Python\Python35\lib\site-packages\django\template\context.py", line 20, in __init__
    super(ContextDict, self).__init__(*args, **kwargs)
ValueError: dictionary update sequence element #0 has length 1; 2 is required
Internal Server Error: /tomo_statistics/graf_test/2/
Traceback (most recent call last):
  File "C:\Users\Samo\AppData\Local\Programs\Python\Python35\lib\site-packages\django\core\handlers\base.py", line 149, in get_response
    response = self.process_exception_by_middleware(e, request)
  File "C:\Users\Samo\AppData\Local\Programs\Python\Python35\lib\site-packages\django\core\handlers\base.py", line 147, in get_response
    response = wrapped_callback(request, *callback_args, **callback_kwargs)
  File "C:\Users\Samo\Desktop\projekt-tomo\projekt-tomo\web\tomo_statistics\views.py", line 15, in graph
    response = JsonResponse(course.json_za_graf(), safe = False)
  File "C:\Users\Samo\Desktop\projekt-tomo\projekt-tomo\web\tomo_statistics\models.py", line 59, in json_za_graf
    test = {'niz' : str(slovar[solved_atleast])}
NameError: name 'solved_atleast' is not defined
Internal Server Error: /tomo_statistics/graf_test/2/
Traceback (most recent call last):
  File "C:\Users\Samo\AppData\Local\Programs\Python\Python35\lib\site-packages\django\core\handlers\base.py", line 149, in get_response
    response = self.process_exception_by_middleware(e, request)
  File "C:\Users\Samo\AppData\Local\Programs\Python\Python35\lib\site-packages\django\core\handlers\base.py", line 147, in get_response
    response = wrapped_callback(request, *callback_args, **callback_kwargs)
  File "C:\Users\Samo\Desktop\projekt-tomo\projekt-tomo\web\tomo_statistics\views.py", line 15, in graph
    response = JsonResponse(course.json_za_graf(), safe = False)
  File "C:\Users\Samo\AppData\Local\Programs\Python\Python35\lib\site-packages\django\http\response.py", line 505, in __init__
    data = json.dumps(data, cls=encoder, **json_dumps_params)
  File "C:\Users\Samo\AppData\Local\Programs\Python\Python35\lib\json\__init__.py", line 237, in dumps
    **kw).encode(obj)
  File "C:\Users\Samo\AppData\Local\Programs\Python\Python35\lib\json\encoder.py", line 198, in encode
    chunks = self.iterencode(o, _one_shot=True)
  File "C:\Users\Samo\AppData\Local\Programs\Python\Python35\lib\json\encoder.py", line 256, in iterencode
    return _iterencode(o, 0)
  File "C:\Users\Samo\AppData\Local\Programs\Python\Python35\lib\site-packages\django\core\serializers\json.py", line 115, in default
    return super(DjangoJSONEncoder, self).default(o)
  File "C:\Users\Samo\AppData\Local\Programs\Python\Python35\lib\json\encoder.py", line 179, in default
    raise TypeError(repr(o) + " is not JSON serializable")
TypeError: [<ProblemSet: Uporaba seznamov>, <ProblemSet: Nizi uporaba>, <ProblemSet: Izpeljani seznami>, <ProblemSet: Rekurzija>, <ProblemSet: Objektno programiranje>, <ProblemSet: Algoritmi>] is not JSON serializable
Internal Server Error: /tomo_statistics/graf_test/2/
Traceback (most recent call last):
  File "C:\Users\Samo\AppData\Local\Programs\Python\Python35\lib\site-packages\django\core\handlers\base.py", line 149, in get_response
    response = self.process_exception_by_middleware(e, request)
  File "C:\Users\Samo\AppData\Local\Programs\Python\Python35\lib\site-packages\django\core\handlers\base.py", line 147, in get_response
    response = wrapped_callback(request, *callback_args, **callback_kwargs)
  File "C:\Users\Samo\Desktop\projekt-tomo\projekt-tomo\web\tomo_statistics\views.py", line 15, in graph
    return render(request, 'tomo_statistics/graf.html', course.json_za_graf())
  File "C:\Users\Samo\AppData\Local\Programs\Python\Python35\lib\site-packages\django\shortcuts.py", line 67, in render
    template_name, context, request=request, using=using)
  File "C:\Users\Samo\AppData\Local\Programs\Python\Python35\lib\site-packages\django\template\loader.py", line 96, in render_to_string
    template = get_template(template_name, using=using)
  File "C:\Users\Samo\AppData\Local\Programs\Python\Python35\lib\site-packages\django\template\loader.py", line 32, in get_template
    return engine.get_template(template_name, dirs)
  File "C:\Users\Samo\AppData\Local\Programs\Python\Python35\lib\site-packages\django\template\backends\django.py", line 40, in get_template
    return Template(self.engine.get_template(template_name, dirs), self)
  File "C:\Users\Samo\AppData\Local\Programs\Python\Python35\lib\site-packages\django\template\engine.py", line 190, in get_template
    template, origin = self.find_template(template_name, dirs)
  File "C:\Users\Samo\AppData\Local\Programs\Python\Python35\lib\site-packages\django\template\engine.py", line 157, in find_template
    name, template_dirs=dirs, skip=skip,
  File "C:\Users\Samo\AppData\Local\Programs\Python\Python35\lib\site-packages\django\template\loaders\base.py", line 46, in get_template
    contents, origin, origin.template_name, self.engine,
  File "C:\Users\Samo\AppData\Local\Programs\Python\Python35\lib\site-packages\django\template\base.py", line 189, in __init__
    self.nodelist = self.compile_nodelist()
  File "C:\Users\Samo\AppData\Local\Programs\Python\Python35\lib\site-packages\django\template\base.py", line 231, in compile_nodelist
    return parser.parse()
  File "C:\Users\Samo\AppData\Local\Programs\Python\Python35\lib\site-packages\django\template\base.py", line 516, in parse
    raise self.error(token, e)
  File "C:\Users\Samo\AppData\Local\Programs\Python\Python35\lib\site-packages\django\template\base.py", line 514, in parse
    compiled_result = compile_func(self, token)
  File "C:\Users\Samo\AppData\Local\Programs\Python\Python35\lib\site-packages\django\template\loader_tags.py", line 267, in do_extends
    nodelist = parser.parse()
  File "C:\Users\Samo\AppData\Local\Programs\Python\Python35\lib\site-packages\django\template\base.py", line 516, in parse
    raise self.error(token, e)
  File "C:\Users\Samo\AppData\Local\Programs\Python\Python35\lib\site-packages\django\template\base.py", line 514, in parse
    compiled_result = compile_func(self, token)
  File "C:\Users\Samo\AppData\Local\Programs\Python\Python35\lib\site-packages\django\template\loader_tags.py", line 241, in do_block
    nodelist = parser.parse(('endblock',))
  File "C:\Users\Samo\AppData\Local\Programs\Python\Python35\lib\site-packages\django\template\base.py", line 487, in parse
    raise self.error(token, e)
  File "C:\Users\Samo\AppData\Local\Programs\Python\Python35\lib\site-packages\django\template\base.py", line 485, in parse
    filter_expression = self.compile_filter(token.contents)
  File "C:\Users\Samo\AppData\Local\Programs\Python\Python35\lib\site-packages\django\template\base.py", line 601, in compile_filter
    return FilterExpression(token, self)
  File "C:\Users\Samo\AppData\Local\Programs\Python\Python35\lib\site-packages\django\template\base.py", line 695, in __init__
    filter_func = parser.find_filter(filter_name)
  File "C:\Users\Samo\AppData\Local\Programs\Python\Python35\lib\site-packages\django\template\base.py", line 607, in find_filter
    raise TemplateSyntaxError("Invalid filter: '%s'" % filter_name)
django.template.exceptions.TemplateSyntaxError: Invalid filter: 'json'
Internal Server Error: /tomo_statistics/graf_test/2/
Traceback (most recent call last):
  File "C:\Users\Samo\AppData\Local\Programs\Python\Python35\lib\site-packages\django\core\handlers\base.py", line 149, in get_response
    response = self.process_exception_by_middleware(e, request)
  File "C:\Users\Samo\AppData\Local\Programs\Python\Python35\lib\site-packages\django\core\handlers\base.py", line 147, in get_response
    response = wrapped_callback(request, *callback_args, **callback_kwargs)
  File "C:\Users\Samo\Desktop\projekt-tomo\projekt-tomo\web\tomo_statistics\views.py", line 21, in graph
    json_data = json.dumps(course.statistika())
  File "C:\Users\Samo\AppData\Local\Programs\Python\Python35\lib\json\__init__.py", line 230, in dumps
    return _default_encoder.encode(obj)
  File "C:\Users\Samo\AppData\Local\Programs\Python\Python35\lib\json\encoder.py", line 198, in encode
    chunks = self.iterencode(o, _one_shot=True)
  File "C:\Users\Samo\AppData\Local\Programs\Python\Python35\lib\json\encoder.py", line 256, in iterencode
    return _iterencode(o, 0)
  File "C:\Users\Samo\AppData\Local\Programs\Python\Python35\lib\json\encoder.py", line 179, in default
    raise TypeError(repr(o) + " is not JSON serializable")
TypeError: [<User: sbradleyjo>, <User: rfieldsbq>, <User: efox81>, <User: agordonc2>, <User: bhudson1w>, <User: rpowell3b>, <User: jreidcs>, <User: cruizi3>, <User: asimpson1i>, <User: jwestd9>] is not JSON serializable
Internal Server Error: /tomo_statistics/graf_test/2/
Traceback (most recent call last):
  File "C:\Users\Samo\AppData\Local\Programs\Python\Python35\lib\site-packages\django\core\handlers\base.py", line 149, in get_response
    response = self.process_exception_by_middleware(e, request)
  File "C:\Users\Samo\AppData\Local\Programs\Python\Python35\lib\site-packages\django\core\handlers\base.py", line 147, in get_response
    response = wrapped_callback(request, *callback_args, **callback_kwargs)
  File "C:\Users\Samo\Desktop\projekt-tomo\projekt-tomo\web\tomo_statistics\views.py", line 21, in graph
    json_data = json.dumps(course.statistika())
  File "C:\Users\Samo\AppData\Local\Programs\Python\Python35\lib\json\__init__.py", line 230, in dumps
    return _default_encoder.encode(obj)
  File "C:\Users\Samo\AppData\Local\Programs\Python\Python35\lib\json\encoder.py", line 198, in encode
    chunks = self.iterencode(o, _one_shot=True)
  File "C:\Users\Samo\AppData\Local\Programs\Python\Python35\lib\json\encoder.py", line 256, in iterencode
    return _iterencode(o, 0)
  File "C:\Users\Samo\AppData\Local\Programs\Python\Python35\lib\json\encoder.py", line 179, in default
    raise TypeError(repr(o) + " is not JSON serializable")
TypeError: [<ProblemSet: Uporaba seznamov>, <ProblemSet: Nizi uporaba>, <ProblemSet: Izpeljani seznami>, <ProblemSet: Rekurzija>, <ProblemSet: Objektno programiranje>, <ProblemSet: Algoritmi>] is not JSON serializable
Internal Server Error: /tomo_statistics/graf_test/2/
Traceback (most recent call last):
  File "C:\Users\Samo\AppData\Local\Programs\Python\Python35\lib\site-packages\django\core\handlers\base.py", line 149, in get_response
    response = self.process_exception_by_middleware(e, request)
  File "C:\Users\Samo\AppData\Local\Programs\Python\Python35\lib\site-packages\django\core\handlers\base.py", line 147, in get_response
    response = wrapped_callback(request, *callback_args, **callback_kwargs)
  File "C:\Users\Samo\Desktop\projekt-tomo\projekt-tomo\web\tomo_statistics\views.py", line 21, in graph
    json_data = json.dump(course.statistika()['solved_atleast'])
TypeError: dump() missing 1 required positional argument: 'fp'
Not Found: /tomo_statistics//graph_test/2/
Not Found: /tomo_statistics//graf_test/2/
Not Found: /favicon.ico
Internal Server Error: /tomo_statistics/17/
Traceback (most recent call last):
  File "C:\Users\Samo\AppData\Local\Programs\Python\Python35\lib\site-packages\django\core\handlers\base.py", line 149, in get_response
    response = self.process_exception_by_middleware(e, request)
  File "C:\Users\Samo\AppData\Local\Programs\Python\Python35\lib\site-packages\django\core\handlers\base.py", line 147, in get_response
    response = wrapped_callback(request, *callback_args, **callback_kwargs)
  File "C:\Users\Samo\Desktop\projekt-tomo\projekt-tomo\web\tomo_statistics\views.py", line 12, in test_view
    return render(request, 'tomo_statistics/statistika_course.html', course.problem_success())
  File "C:\Users\Samo\Desktop\projekt-tomo\projekt-tomo\web\tomo_statistics\models.py", line 67, in problem_success
    for problem_set in problem_sets:
  File "C:\Users\Samo\AppData\Local\Programs\Python\Python35\lib\site-packages\django\db\models\query.py", line 258, in __iter__
    self._fetch_all()
  File "C:\Users\Samo\AppData\Local\Programs\Python\Python35\lib\site-packages\django\db\models\query.py", line 1076, in _fetch_all
    self._prefetch_related_objects()
  File "C:\Users\Samo\AppData\Local\Programs\Python\Python35\lib\site-packages\django\db\models\query.py", line 656, in _prefetch_related_objects
    prefetch_related_objects(self._result_cache, self._prefetch_related_lookups)
  File "C:\Users\Samo\AppData\Local\Programs\Python\Python35\lib\site-packages\django\db\models\query.py", line 1454, in prefetch_related_objects
    "prefetch_related()." % lookup.prefetch_through)
ValueError: 'problems__parts__attempts__valid' does not resolve to an item that supports prefetching - this is an invalid parameter to prefetch_related().
Internal Server Error: /tomo_statistics/2/
Traceback (most recent call last):
  File "C:\Users\Samo\AppData\Local\Programs\Python\Python35\lib\site-packages\django\core\handlers\base.py", line 149, in get_response
    response = self.process_exception_by_middleware(e, request)
  File "C:\Users\Samo\AppData\Local\Programs\Python\Python35\lib\site-packages\django\core\handlers\base.py", line 147, in get_response
    response = wrapped_callback(request, *callback_args, **callback_kwargs)
  File "C:\Users\Samo\Desktop\projekt-tomo\projekt-tomo\web\tomo_statistics\views.py", line 12, in test_view
    return render(request, 'tomo_statistics/statistika_course.html', course.problem_success())
  File "C:\Users\Samo\Desktop\projekt-tomo\projekt-tomo\web\tomo_statistics\models.py", line 67, in problem_success
    for problem_set in problem_sets:
  File "C:\Users\Samo\AppData\Local\Programs\Python\Python35\lib\site-packages\django\db\models\query.py", line 258, in __iter__
    self._fetch_all()
  File "C:\Users\Samo\AppData\Local\Programs\Python\Python35\lib\site-packages\django\db\models\query.py", line 1076, in _fetch_all
    self._prefetch_related_objects()
  File "C:\Users\Samo\AppData\Local\Programs\Python\Python35\lib\site-packages\django\db\models\query.py", line 656, in _prefetch_related_objects
    prefetch_related_objects(self._result_cache, self._prefetch_related_lookups)
  File "C:\Users\Samo\AppData\Local\Programs\Python\Python35\lib\site-packages\django\db\models\query.py", line 1454, in prefetch_related_objects
    "prefetch_related()." % lookup.prefetch_through)
ValueError: 'problems__parts__attempts__valid' does not resolve to an item that supports prefetching - this is an invalid parameter to prefetch_related().
Internal Server Error: /tomo_statistics/17/
Traceback (most recent call last):
  File "C:\Users\Samo\AppData\Local\Programs\Python\Python35\lib\site-packages\django\core\handlers\base.py", line 149, in get_response
    response = self.process_exception_by_middleware(e, request)
  File "C:\Users\Samo\AppData\Local\Programs\Python\Python35\lib\site-packages\django\core\handlers\base.py", line 147, in get_response
    response = wrapped_callback(request, *callback_args, **callback_kwargs)
  File "C:\Users\Samo\Desktop\projekt-tomo\projekt-tomo\web\tomo_statistics\views.py", line 12, in test_view
    json_correct = json.dumps(course.problem_success()['correct_submissions'])
  File "C:\Users\Samo\Desktop\projekt-tomo\projekt-tomo\web\tomo_statistics\models.py", line 64, in problem_success
    data = [['Correct_submissions', 'Incorrect_submissions', { role: 'annotation' }]]
NameError: name 'role' is not defined
Not Found: /favicon.ico
Not Found: /favicon.ico
Not Found: /favicon.ico
Internal Server Error: /admin/users/user/add/
Traceback (most recent call last):
  File "C:\Users\Samo\AppData\Local\Programs\Python\Python35\lib\site-packages\django\core\handlers\base.py", line 149, in get_response
    response = self.process_exception_by_middleware(e, request)
  File "C:\Users\Samo\AppData\Local\Programs\Python\Python35\lib\site-packages\django\core\handlers\base.py", line 147, in get_response
    response = wrapped_callback(request, *callback_args, **callback_kwargs)
  File "C:\Users\Samo\AppData\Local\Programs\Python\Python35\lib\site-packages\django\contrib\admin\options.py", line 541, in wrapper
    return self.admin_site.admin_view(view)(*args, **kwargs)
  File "C:\Users\Samo\AppData\Local\Programs\Python\Python35\lib\site-packages\django\utils\decorators.py", line 149, in _wrapped_view
    response = view_func(request, *args, **kwargs)
  File "C:\Users\Samo\AppData\Local\Programs\Python\Python35\lib\site-packages\django\views\decorators\cache.py", line 57, in _wrapped_view_func
    response = view_func(request, *args, **kwargs)
  File "C:\Users\Samo\AppData\Local\Programs\Python\Python35\lib\site-packages\django\contrib\admin\sites.py", line 244, in inner
    return view(request, *args, **kwargs)
  File "C:\Users\Samo\AppData\Local\Programs\Python\Python35\lib\site-packages\django\utils\decorators.py", line 67, in _wrapper
    return bound_func(*args, **kwargs)
  File "C:\Users\Samo\AppData\Local\Programs\Python\Python35\lib\site-packages\django\views\decorators\debug.py", line 76, in sensitive_post_parameters_wrapper
    return view(request, *args, **kwargs)
  File "C:\Users\Samo\AppData\Local\Programs\Python\Python35\lib\site-packages\django\utils\decorators.py", line 63, in bound_func
    return func.__get__(self, type(self))(*args2, **kwargs2)
  File "C:\Users\Samo\AppData\Local\Programs\Python\Python35\lib\site-packages\django\utils\decorators.py", line 67, in _wrapper
    return bound_func(*args, **kwargs)
  File "C:\Users\Samo\AppData\Local\Programs\Python\Python35\lib\site-packages\django\utils\decorators.py", line 149, in _wrapped_view
    response = view_func(request, *args, **kwargs)
  File "C:\Users\Samo\AppData\Local\Programs\Python\Python35\lib\site-packages\django\utils\decorators.py", line 63, in bound_func
    return func.__get__(self, type(self))(*args2, **kwargs2)
  File "C:\Users\Samo\AppData\Local\Programs\Python\Python35\lib\contextlib.py", line 30, in inner
    return func(*args, **kwds)
  File "C:\Users\Samo\AppData\Local\Programs\Python\Python35\lib\site-packages\django\contrib\auth\admin.py", line 128, in add_view
    extra_context)
  File "C:\Users\Samo\AppData\Local\Programs\Python\Python35\lib\site-packages\django\contrib\admin\options.py", line 1437, in add_view
    return self.changeform_view(request, None, form_url, extra_context)
  File "C:\Users\Samo\AppData\Local\Programs\Python\Python35\lib\site-packages\django\utils\decorators.py", line 67, in _wrapper
    return bound_func(*args, **kwargs)
  File "C:\Users\Samo\AppData\Local\Programs\Python\Python35\lib\site-packages\django\utils\decorators.py", line 149, in _wrapped_view
    response = view_func(request, *args, **kwargs)
  File "C:\Users\Samo\AppData\Local\Programs\Python\Python35\lib\site-packages\django\utils\decorators.py", line 63, in bound_func
    return func.__get__(self, type(self))(*args2, **kwargs2)
  File "C:\Users\Samo\AppData\Local\Programs\Python\Python35\lib\contextlib.py", line 30, in inner
    return func(*args, **kwds)
  File "C:\Users\Samo\AppData\Local\Programs\Python\Python35\lib\site-packages\django\contrib\admin\options.py", line 1370, in changeform_view
    if form.is_valid():
  File "C:\Users\Samo\AppData\Local\Programs\Python\Python35\lib\site-packages\django\forms\forms.py", line 161, in is_valid
    return self.is_bound and not self.errors
  File "C:\Users\Samo\AppData\Local\Programs\Python\Python35\lib\site-packages\django\forms\forms.py", line 153, in errors
    self.full_clean()
  File "C:\Users\Samo\AppData\Local\Programs\Python\Python35\lib\site-packages\django\forms\forms.py", line 362, in full_clean
    self._clean_fields()
  File "C:\Users\Samo\AppData\Local\Programs\Python\Python35\lib\site-packages\django\forms\forms.py", line 383, in _clean_fields
    value = getattr(self, 'clean_%s' % name)()
  File "C:\Users\Samo\Desktop\projekt-tomo\projekt-tomo\web\users\admin.py", line 18, in clean_username
    raise forms.ValidationError(self.error_messages['duplicate_username'])
KeyError: 'duplicate_username'
Internal Server Error: /admin/users/user/add/
Traceback (most recent call last):
  File "C:\Users\Samo\AppData\Local\Programs\Python\Python35\lib\site-packages\django\core\handlers\base.py", line 149, in get_response
    response = self.process_exception_by_middleware(e, request)
  File "C:\Users\Samo\AppData\Local\Programs\Python\Python35\lib\site-packages\django\core\handlers\base.py", line 147, in get_response
    response = wrapped_callback(request, *callback_args, **callback_kwargs)
  File "C:\Users\Samo\AppData\Local\Programs\Python\Python35\lib\site-packages\django\contrib\admin\options.py", line 541, in wrapper
    return self.admin_site.admin_view(view)(*args, **kwargs)
  File "C:\Users\Samo\AppData\Local\Programs\Python\Python35\lib\site-packages\django\utils\decorators.py", line 149, in _wrapped_view
    response = view_func(request, *args, **kwargs)
  File "C:\Users\Samo\AppData\Local\Programs\Python\Python35\lib\site-packages\django\views\decorators\cache.py", line 57, in _wrapped_view_func
    response = view_func(request, *args, **kwargs)
  File "C:\Users\Samo\AppData\Local\Programs\Python\Python35\lib\site-packages\django\contrib\admin\sites.py", line 244, in inner
    return view(request, *args, **kwargs)
  File "C:\Users\Samo\AppData\Local\Programs\Python\Python35\lib\site-packages\django\utils\decorators.py", line 67, in _wrapper
    return bound_func(*args, **kwargs)
  File "C:\Users\Samo\AppData\Local\Programs\Python\Python35\lib\site-packages\django\views\decorators\debug.py", line 76, in sensitive_post_parameters_wrapper
    return view(request, *args, **kwargs)
  File "C:\Users\Samo\AppData\Local\Programs\Python\Python35\lib\site-packages\django\utils\decorators.py", line 63, in bound_func
    return func.__get__(self, type(self))(*args2, **kwargs2)
  File "C:\Users\Samo\AppData\Local\Programs\Python\Python35\lib\site-packages\django\utils\decorators.py", line 67, in _wrapper
    return bound_func(*args, **kwargs)
  File "C:\Users\Samo\AppData\Local\Programs\Python\Python35\lib\site-packages\django\utils\decorators.py", line 149, in _wrapped_view
    response = view_func(request, *args, **kwargs)
  File "C:\Users\Samo\AppData\Local\Programs\Python\Python35\lib\site-packages\django\utils\decorators.py", line 63, in bound_func
    return func.__get__(self, type(self))(*args2, **kwargs2)
  File "C:\Users\Samo\AppData\Local\Programs\Python\Python35\lib\contextlib.py", line 30, in inner
    return func(*args, **kwds)
  File "C:\Users\Samo\AppData\Local\Programs\Python\Python35\lib\site-packages\django\contrib\auth\admin.py", line 128, in add_view
    extra_context)
  File "C:\Users\Samo\AppData\Local\Programs\Python\Python35\lib\site-packages\django\contrib\admin\options.py", line 1437, in add_view
    return self.changeform_view(request, None, form_url, extra_context)
  File "C:\Users\Samo\AppData\Local\Programs\Python\Python35\lib\site-packages\django\utils\decorators.py", line 67, in _wrapper
    return bound_func(*args, **kwargs)
  File "C:\Users\Samo\AppData\Local\Programs\Python\Python35\lib\site-packages\django\utils\decorators.py", line 149, in _wrapped_view
    response = view_func(request, *args, **kwargs)
  File "C:\Users\Samo\AppData\Local\Programs\Python\Python35\lib\site-packages\django\utils\decorators.py", line 63, in bound_func
    return func.__get__(self, type(self))(*args2, **kwargs2)
  File "C:\Users\Samo\AppData\Local\Programs\Python\Python35\lib\contextlib.py", line 30, in inner
    return func(*args, **kwds)
  File "C:\Users\Samo\AppData\Local\Programs\Python\Python35\lib\site-packages\django\contrib\admin\options.py", line 1370, in changeform_view
    if form.is_valid():
  File "C:\Users\Samo\AppData\Local\Programs\Python\Python35\lib\site-packages\django\forms\forms.py", line 161, in is_valid
    return self.is_bound and not self.errors
  File "C:\Users\Samo\AppData\Local\Programs\Python\Python35\lib\site-packages\django\forms\forms.py", line 153, in errors
    self.full_clean()
  File "C:\Users\Samo\AppData\Local\Programs\Python\Python35\lib\site-packages\django\forms\forms.py", line 362, in full_clean
    self._clean_fields()
  File "C:\Users\Samo\AppData\Local\Programs\Python\Python35\lib\site-packages\django\forms\forms.py", line 383, in _clean_fields
    value = getattr(self, 'clean_%s' % name)()
  File "C:\Users\Samo\Desktop\projekt-tomo\projekt-tomo\web\users\admin.py", line 18, in clean_username
    raise forms.ValidationError(self.error_messages['duplicate_username'])
KeyError: 'duplicate_username'
Internal Server Error: /admin/users/user/add/
Traceback (most recent call last):
  File "C:\Users\Samo\AppData\Local\Programs\Python\Python35\lib\site-packages\django\core\handlers\base.py", line 149, in get_response
    response = self.process_exception_by_middleware(e, request)
  File "C:\Users\Samo\AppData\Local\Programs\Python\Python35\lib\site-packages\django\core\handlers\base.py", line 147, in get_response
    response = wrapped_callback(request, *callback_args, **callback_kwargs)
  File "C:\Users\Samo\AppData\Local\Programs\Python\Python35\lib\site-packages\django\contrib\admin\options.py", line 541, in wrapper
    return self.admin_site.admin_view(view)(*args, **kwargs)
  File "C:\Users\Samo\AppData\Local\Programs\Python\Python35\lib\site-packages\django\utils\decorators.py", line 149, in _wrapped_view
    response = view_func(request, *args, **kwargs)
  File "C:\Users\Samo\AppData\Local\Programs\Python\Python35\lib\site-packages\django\views\decorators\cache.py", line 57, in _wrapped_view_func
    response = view_func(request, *args, **kwargs)
  File "C:\Users\Samo\AppData\Local\Programs\Python\Python35\lib\site-packages\django\contrib\admin\sites.py", line 244, in inner
    return view(request, *args, **kwargs)
  File "C:\Users\Samo\AppData\Local\Programs\Python\Python35\lib\site-packages\django\utils\decorators.py", line 67, in _wrapper
    return bound_func(*args, **kwargs)
  File "C:\Users\Samo\AppData\Local\Programs\Python\Python35\lib\site-packages\django\views\decorators\debug.py", line 76, in sensitive_post_parameters_wrapper
    return view(request, *args, **kwargs)
  File "C:\Users\Samo\AppData\Local\Programs\Python\Python35\lib\site-packages\django\utils\decorators.py", line 63, in bound_func
    return func.__get__(self, type(self))(*args2, **kwargs2)
  File "C:\Users\Samo\AppData\Local\Programs\Python\Python35\lib\site-packages\django\utils\decorators.py", line 67, in _wrapper
    return bound_func(*args, **kwargs)
  File "C:\Users\Samo\AppData\Local\Programs\Python\Python35\lib\site-packages\django\utils\decorators.py", line 149, in _wrapped_view
    response = view_func(request, *args, **kwargs)
  File "C:\Users\Samo\AppData\Local\Programs\Python\Python35\lib\site-packages\django\utils\decorators.py", line 63, in bound_func
    return func.__get__(self, type(self))(*args2, **kwargs2)
  File "C:\Users\Samo\AppData\Local\Programs\Python\Python35\lib\contextlib.py", line 30, in inner
    return func(*args, **kwds)
  File "C:\Users\Samo\AppData\Local\Programs\Python\Python35\lib\site-packages\django\contrib\auth\admin.py", line 128, in add_view
    extra_context)
  File "C:\Users\Samo\AppData\Local\Programs\Python\Python35\lib\site-packages\django\contrib\admin\options.py", line 1437, in add_view
    return self.changeform_view(request, None, form_url, extra_context)
  File "C:\Users\Samo\AppData\Local\Programs\Python\Python35\lib\site-packages\django\utils\decorators.py", line 67, in _wrapper
    return bound_func(*args, **kwargs)
  File "C:\Users\Samo\AppData\Local\Programs\Python\Python35\lib\site-packages\django\utils\decorators.py", line 149, in _wrapped_view
    response = view_func(request, *args, **kwargs)
  File "C:\Users\Samo\AppData\Local\Programs\Python\Python35\lib\site-packages\django\utils\decorators.py", line 63, in bound_func
    return func.__get__(self, type(self))(*args2, **kwargs2)
  File "C:\Users\Samo\AppData\Local\Programs\Python\Python35\lib\contextlib.py", line 30, in inner
    return func(*args, **kwds)
  File "C:\Users\Samo\AppData\Local\Programs\Python\Python35\lib\site-packages\django\contrib\admin\options.py", line 1370, in changeform_view
    if form.is_valid():
  File "C:\Users\Samo\AppData\Local\Programs\Python\Python35\lib\site-packages\django\forms\forms.py", line 161, in is_valid
    return self.is_bound and not self.errors
  File "C:\Users\Samo\AppData\Local\Programs\Python\Python35\lib\site-packages\django\forms\forms.py", line 153, in errors
    self.full_clean()
  File "C:\Users\Samo\AppData\Local\Programs\Python\Python35\lib\site-packages\django\forms\forms.py", line 362, in full_clean
    self._clean_fields()
  File "C:\Users\Samo\AppData\Local\Programs\Python\Python35\lib\site-packages\django\forms\forms.py", line 383, in _clean_fields
    value = getattr(self, 'clean_%s' % name)()
  File "C:\Users\Samo\Desktop\projekt-tomo\projekt-tomo\web\users\admin.py", line 18, in clean_username
    raise forms.ValidationError(self.error_messages['duplicate_username'])
KeyError: 'duplicate_username'
Internal Server Error: /admin/users/user/add/
Traceback (most recent call last):
  File "C:\Users\Samo\AppData\Local\Programs\Python\Python35\lib\site-packages\django\core\handlers\base.py", line 149, in get_response
    response = self.process_exception_by_middleware(e, request)
  File "C:\Users\Samo\AppData\Local\Programs\Python\Python35\lib\site-packages\django\core\handlers\base.py", line 147, in get_response
    response = wrapped_callback(request, *callback_args, **callback_kwargs)
  File "C:\Users\Samo\AppData\Local\Programs\Python\Python35\lib\site-packages\django\contrib\admin\options.py", line 541, in wrapper
    return self.admin_site.admin_view(view)(*args, **kwargs)
  File "C:\Users\Samo\AppData\Local\Programs\Python\Python35\lib\site-packages\django\utils\decorators.py", line 149, in _wrapped_view
    response = view_func(request, *args, **kwargs)
  File "C:\Users\Samo\AppData\Local\Programs\Python\Python35\lib\site-packages\django\views\decorators\cache.py", line 57, in _wrapped_view_func
    response = view_func(request, *args, **kwargs)
  File "C:\Users\Samo\AppData\Local\Programs\Python\Python35\lib\site-packages\django\contrib\admin\sites.py", line 244, in inner
    return view(request, *args, **kwargs)
  File "C:\Users\Samo\AppData\Local\Programs\Python\Python35\lib\site-packages\django\utils\decorators.py", line 67, in _wrapper
    return bound_func(*args, **kwargs)
  File "C:\Users\Samo\AppData\Local\Programs\Python\Python35\lib\site-packages\django\views\decorators\debug.py", line 76, in sensitive_post_parameters_wrapper
    return view(request, *args, **kwargs)
  File "C:\Users\Samo\AppData\Local\Programs\Python\Python35\lib\site-packages\django\utils\decorators.py", line 63, in bound_func
    return func.__get__(self, type(self))(*args2, **kwargs2)
  File "C:\Users\Samo\AppData\Local\Programs\Python\Python35\lib\site-packages\django\utils\decorators.py", line 67, in _wrapper
    return bound_func(*args, **kwargs)
  File "C:\Users\Samo\AppData\Local\Programs\Python\Python35\lib\site-packages\django\utils\decorators.py", line 149, in _wrapped_view
    response = view_func(request, *args, **kwargs)
  File "C:\Users\Samo\AppData\Local\Programs\Python\Python35\lib\site-packages\django\utils\decorators.py", line 63, in bound_func
    return func.__get__(self, type(self))(*args2, **kwargs2)
  File "C:\Users\Samo\AppData\Local\Programs\Python\Python35\lib\contextlib.py", line 30, in inner
    return func(*args, **kwds)
  File "C:\Users\Samo\AppData\Local\Programs\Python\Python35\lib\site-packages\django\contrib\auth\admin.py", line 128, in add_view
    extra_context)
  File "C:\Users\Samo\AppData\Local\Programs\Python\Python35\lib\site-packages\django\contrib\admin\options.py", line 1437, in add_view
    return self.changeform_view(request, None, form_url, extra_context)
  File "C:\Users\Samo\AppData\Local\Programs\Python\Python35\lib\site-packages\django\utils\decorators.py", line 67, in _wrapper
    return bound_func(*args, **kwargs)
  File "C:\Users\Samo\AppData\Local\Programs\Python\Python35\lib\site-packages\django\utils\decorators.py", line 149, in _wrapped_view
    response = view_func(request, *args, **kwargs)
  File "C:\Users\Samo\AppData\Local\Programs\Python\Python35\lib\site-packages\django\utils\decorators.py", line 63, in bound_func
    return func.__get__(self, type(self))(*args2, **kwargs2)
  File "C:\Users\Samo\AppData\Local\Programs\Python\Python35\lib\contextlib.py", line 30, in inner
    return func(*args, **kwds)
  File "C:\Users\Samo\AppData\Local\Programs\Python\Python35\lib\site-packages\django\contrib\admin\options.py", line 1370, in changeform_view
    if form.is_valid():
  File "C:\Users\Samo\AppData\Local\Programs\Python\Python35\lib\site-packages\django\forms\forms.py", line 161, in is_valid
    return self.is_bound and not self.errors
  File "C:\Users\Samo\AppData\Local\Programs\Python\Python35\lib\site-packages\django\forms\forms.py", line 153, in errors
    self.full_clean()
  File "C:\Users\Samo\AppData\Local\Programs\Python\Python35\lib\site-packages\django\forms\forms.py", line 362, in full_clean
    self._clean_fields()
  File "C:\Users\Samo\AppData\Local\Programs\Python\Python35\lib\site-packages\django\forms\forms.py", line 383, in _clean_fields
    value = getattr(self, 'clean_%s' % name)()
  File "C:\Users\Samo\Desktop\projekt-tomo\projekt-tomo\web\users\admin.py", line 18, in clean_username
    raise forms.ValidationError(self.error_messages['duplicate_username'])
KeyError: 'duplicate_username'
Internal Server Error: /admin/users/user/add/
Traceback (most recent call last):
  File "C:\Users\Samo\AppData\Local\Programs\Python\Python35\lib\site-packages\django\core\handlers\base.py", line 149, in get_response
    response = self.process_exception_by_middleware(e, request)
  File "C:\Users\Samo\AppData\Local\Programs\Python\Python35\lib\site-packages\django\core\handlers\base.py", line 147, in get_response
    response = wrapped_callback(request, *callback_args, **callback_kwargs)
  File "C:\Users\Samo\AppData\Local\Programs\Python\Python35\lib\site-packages\django\contrib\admin\options.py", line 541, in wrapper
    return self.admin_site.admin_view(view)(*args, **kwargs)
  File "C:\Users\Samo\AppData\Local\Programs\Python\Python35\lib\site-packages\django\utils\decorators.py", line 149, in _wrapped_view
    response = view_func(request, *args, **kwargs)
  File "C:\Users\Samo\AppData\Local\Programs\Python\Python35\lib\site-packages\django\views\decorators\cache.py", line 57, in _wrapped_view_func
    response = view_func(request, *args, **kwargs)
  File "C:\Users\Samo\AppData\Local\Programs\Python\Python35\lib\site-packages\django\contrib\admin\sites.py", line 244, in inner
    return view(request, *args, **kwargs)
  File "C:\Users\Samo\AppData\Local\Programs\Python\Python35\lib\site-packages\django\utils\decorators.py", line 67, in _wrapper
    return bound_func(*args, **kwargs)
  File "C:\Users\Samo\AppData\Local\Programs\Python\Python35\lib\site-packages\django\views\decorators\debug.py", line 76, in sensitive_post_parameters_wrapper
    return view(request, *args, **kwargs)
  File "C:\Users\Samo\AppData\Local\Programs\Python\Python35\lib\site-packages\django\utils\decorators.py", line 63, in bound_func
    return func.__get__(self, type(self))(*args2, **kwargs2)
  File "C:\Users\Samo\AppData\Local\Programs\Python\Python35\lib\site-packages\django\utils\decorators.py", line 67, in _wrapper
    return bound_func(*args, **kwargs)
  File "C:\Users\Samo\AppData\Local\Programs\Python\Python35\lib\site-packages\django\utils\decorators.py", line 149, in _wrapped_view
    response = view_func(request, *args, **kwargs)
  File "C:\Users\Samo\AppData\Local\Programs\Python\Python35\lib\site-packages\django\utils\decorators.py", line 63, in bound_func
    return func.__get__(self, type(self))(*args2, **kwargs2)
  File "C:\Users\Samo\AppData\Local\Programs\Python\Python35\lib\contextlib.py", line 30, in inner
    return func(*args, **kwds)
  File "C:\Users\Samo\AppData\Local\Programs\Python\Python35\lib\site-packages\django\contrib\auth\admin.py", line 128, in add_view
    extra_context)
  File "C:\Users\Samo\AppData\Local\Programs\Python\Python35\lib\site-packages\django\contrib\admin\options.py", line 1437, in add_view
    return self.changeform_view(request, None, form_url, extra_context)
  File "C:\Users\Samo\AppData\Local\Programs\Python\Python35\lib\site-packages\django\utils\decorators.py", line 67, in _wrapper
    return bound_func(*args, **kwargs)
  File "C:\Users\Samo\AppData\Local\Programs\Python\Python35\lib\site-packages\django\utils\decorators.py", line 149, in _wrapped_view
    response = view_func(request, *args, **kwargs)
  File "C:\Users\Samo\AppData\Local\Programs\Python\Python35\lib\site-packages\django\utils\decorators.py", line 63, in bound_func
    return func.__get__(self, type(self))(*args2, **kwargs2)
  File "C:\Users\Samo\AppData\Local\Programs\Python\Python35\lib\contextlib.py", line 30, in inner
    return func(*args, **kwds)
  File "C:\Users\Samo\AppData\Local\Programs\Python\Python35\lib\site-packages\django\contrib\admin\options.py", line 1370, in changeform_view
    if form.is_valid():
  File "C:\Users\Samo\AppData\Local\Programs\Python\Python35\lib\site-packages\django\forms\forms.py", line 161, in is_valid
    return self.is_bound and not self.errors
  File "C:\Users\Samo\AppData\Local\Programs\Python\Python35\lib\site-packages\django\forms\forms.py", line 153, in errors
    self.full_clean()
  File "C:\Users\Samo\AppData\Local\Programs\Python\Python35\lib\site-packages\django\forms\forms.py", line 362, in full_clean
    self._clean_fields()
  File "C:\Users\Samo\AppData\Local\Programs\Python\Python35\lib\site-packages\django\forms\forms.py", line 383, in _clean_fields
    value = getattr(self, 'clean_%s' % name)()
  File "C:\Users\Samo\Desktop\projekt-tomo\projekt-tomo\web\users\admin.py", line 18, in clean_username
    raise forms.ValidationError(self.error_messages['duplicate_username'])
KeyError: 'duplicate_username'
Internal Server Error: /admin/users/user/add/
Traceback (most recent call last):
  File "C:\Users\Samo\AppData\Local\Programs\Python\Python35\lib\site-packages\django\core\handlers\base.py", line 149, in get_response
    response = self.process_exception_by_middleware(e, request)
  File "C:\Users\Samo\AppData\Local\Programs\Python\Python35\lib\site-packages\django\core\handlers\base.py", line 147, in get_response
    response = wrapped_callback(request, *callback_args, **callback_kwargs)
  File "C:\Users\Samo\AppData\Local\Programs\Python\Python35\lib\site-packages\django\contrib\admin\options.py", line 541, in wrapper
    return self.admin_site.admin_view(view)(*args, **kwargs)
  File "C:\Users\Samo\AppData\Local\Programs\Python\Python35\lib\site-packages\django\utils\decorators.py", line 149, in _wrapped_view
    response = view_func(request, *args, **kwargs)
  File "C:\Users\Samo\AppData\Local\Programs\Python\Python35\lib\site-packages\django\views\decorators\cache.py", line 57, in _wrapped_view_func
    response = view_func(request, *args, **kwargs)
  File "C:\Users\Samo\AppData\Local\Programs\Python\Python35\lib\site-packages\django\contrib\admin\sites.py", line 244, in inner
    return view(request, *args, **kwargs)
  File "C:\Users\Samo\AppData\Local\Programs\Python\Python35\lib\site-packages\django\utils\decorators.py", line 67, in _wrapper
    return bound_func(*args, **kwargs)
  File "C:\Users\Samo\AppData\Local\Programs\Python\Python35\lib\site-packages\django\views\decorators\debug.py", line 76, in sensitive_post_parameters_wrapper
    return view(request, *args, **kwargs)
  File "C:\Users\Samo\AppData\Local\Programs\Python\Python35\lib\site-packages\django\utils\decorators.py", line 63, in bound_func
    return func.__get__(self, type(self))(*args2, **kwargs2)
  File "C:\Users\Samo\AppData\Local\Programs\Python\Python35\lib\site-packages\django\utils\decorators.py", line 67, in _wrapper
    return bound_func(*args, **kwargs)
  File "C:\Users\Samo\AppData\Local\Programs\Python\Python35\lib\site-packages\django\utils\decorators.py", line 149, in _wrapped_view
    response = view_func(request, *args, **kwargs)
  File "C:\Users\Samo\AppData\Local\Programs\Python\Python35\lib\site-packages\django\utils\decorators.py", line 63, in bound_func
    return func.__get__(self, type(self))(*args2, **kwargs2)
  File "C:\Users\Samo\AppData\Local\Programs\Python\Python35\lib\contextlib.py", line 30, in inner
    return func(*args, **kwds)
  File "C:\Users\Samo\AppData\Local\Programs\Python\Python35\lib\site-packages\django\contrib\auth\admin.py", line 128, in add_view
    extra_context)
  File "C:\Users\Samo\AppData\Local\Programs\Python\Python35\lib\site-packages\django\contrib\admin\options.py", line 1437, in add_view
    return self.changeform_view(request, None, form_url, extra_context)
  File "C:\Users\Samo\AppData\Local\Programs\Python\Python35\lib\site-packages\django\utils\decorators.py", line 67, in _wrapper
    return bound_func(*args, **kwargs)
  File "C:\Users\Samo\AppData\Local\Programs\Python\Python35\lib\site-packages\django\utils\decorators.py", line 149, in _wrapped_view
    response = view_func(request, *args, **kwargs)
  File "C:\Users\Samo\AppData\Local\Programs\Python\Python35\lib\site-packages\django\utils\decorators.py", line 63, in bound_func
    return func.__get__(self, type(self))(*args2, **kwargs2)
  File "C:\Users\Samo\AppData\Local\Programs\Python\Python35\lib\contextlib.py", line 30, in inner
    return func(*args, **kwds)
  File "C:\Users\Samo\AppData\Local\Programs\Python\Python35\lib\site-packages\django\contrib\admin\options.py", line 1370, in changeform_view
    if form.is_valid():
  File "C:\Users\Samo\AppData\Local\Programs\Python\Python35\lib\site-packages\django\forms\forms.py", line 161, in is_valid
    return self.is_bound and not self.errors
  File "C:\Users\Samo\AppData\Local\Programs\Python\Python35\lib\site-packages\django\forms\forms.py", line 153, in errors
    self.full_clean()
  File "C:\Users\Samo\AppData\Local\Programs\Python\Python35\lib\site-packages\django\forms\forms.py", line 362, in full_clean
    self._clean_fields()
  File "C:\Users\Samo\AppData\Local\Programs\Python\Python35\lib\site-packages\django\forms\forms.py", line 383, in _clean_fields
    value = getattr(self, 'clean_%s' % name)()
  File "C:\Users\Samo\Desktop\projekt-tomo\projekt-tomo\web\users\admin.py", line 18, in clean_username
    raise forms.ValidationError(self.error_messages['duplicate_username'])
KeyError: 'duplicate_username'
Internal Server Error: /admin/users/user/add/
Traceback (most recent call last):
  File "C:\Users\Samo\AppData\Local\Programs\Python\Python35\lib\site-packages\django\core\handlers\base.py", line 149, in get_response
    response = self.process_exception_by_middleware(e, request)
  File "C:\Users\Samo\AppData\Local\Programs\Python\Python35\lib\site-packages\django\core\handlers\base.py", line 147, in get_response
    response = wrapped_callback(request, *callback_args, **callback_kwargs)
  File "C:\Users\Samo\AppData\Local\Programs\Python\Python35\lib\site-packages\django\contrib\admin\options.py", line 541, in wrapper
    return self.admin_site.admin_view(view)(*args, **kwargs)
  File "C:\Users\Samo\AppData\Local\Programs\Python\Python35\lib\site-packages\django\utils\decorators.py", line 149, in _wrapped_view
    response = view_func(request, *args, **kwargs)
  File "C:\Users\Samo\AppData\Local\Programs\Python\Python35\lib\site-packages\django\views\decorators\cache.py", line 57, in _wrapped_view_func
    response = view_func(request, *args, **kwargs)
  File "C:\Users\Samo\AppData\Local\Programs\Python\Python35\lib\site-packages\django\contrib\admin\sites.py", line 244, in inner
    return view(request, *args, **kwargs)
  File "C:\Users\Samo\AppData\Local\Programs\Python\Python35\lib\site-packages\django\utils\decorators.py", line 67, in _wrapper
    return bound_func(*args, **kwargs)
  File "C:\Users\Samo\AppData\Local\Programs\Python\Python35\lib\site-packages\django\views\decorators\debug.py", line 76, in sensitive_post_parameters_wrapper
    return view(request, *args, **kwargs)
  File "C:\Users\Samo\AppData\Local\Programs\Python\Python35\lib\site-packages\django\utils\decorators.py", line 63, in bound_func
    return func.__get__(self, type(self))(*args2, **kwargs2)
  File "C:\Users\Samo\AppData\Local\Programs\Python\Python35\lib\site-packages\django\utils\decorators.py", line 67, in _wrapper
    return bound_func(*args, **kwargs)
  File "C:\Users\Samo\AppData\Local\Programs\Python\Python35\lib\site-packages\django\utils\decorators.py", line 149, in _wrapped_view
    response = view_func(request, *args, **kwargs)
  File "C:\Users\Samo\AppData\Local\Programs\Python\Python35\lib\site-packages\django\utils\decorators.py", line 63, in bound_func
    return func.__get__(self, type(self))(*args2, **kwargs2)
  File "C:\Users\Samo\AppData\Local\Programs\Python\Python35\lib\contextlib.py", line 30, in inner
    return func(*args, **kwds)
  File "C:\Users\Samo\AppData\Local\Programs\Python\Python35\lib\site-packages\django\contrib\auth\admin.py", line 128, in add_view
    extra_context)
  File "C:\Users\Samo\AppData\Local\Programs\Python\Python35\lib\site-packages\django\contrib\admin\options.py", line 1437, in add_view
    return self.changeform_view(request, None, form_url, extra_context)
  File "C:\Users\Samo\AppData\Local\Programs\Python\Python35\lib\site-packages\django\utils\decorators.py", line 67, in _wrapper
    return bound_func(*args, **kwargs)
  File "C:\Users\Samo\AppData\Local\Programs\Python\Python35\lib\site-packages\django\utils\decorators.py", line 149, in _wrapped_view
    response = view_func(request, *args, **kwargs)
  File "C:\Users\Samo\AppData\Local\Programs\Python\Python35\lib\site-packages\django\utils\decorators.py", line 63, in bound_func
    return func.__get__(self, type(self))(*args2, **kwargs2)
  File "C:\Users\Samo\AppData\Local\Programs\Python\Python35\lib\contextlib.py", line 30, in inner
    return func(*args, **kwds)
  File "C:\Users\Samo\AppData\Local\Programs\Python\Python35\lib\site-packages\django\contrib\admin\options.py", line 1370, in changeform_view
    if form.is_valid():
  File "C:\Users\Samo\AppData\Local\Programs\Python\Python35\lib\site-packages\django\forms\forms.py", line 161, in is_valid
    return self.is_bound and not self.errors
  File "C:\Users\Samo\AppData\Local\Programs\Python\Python35\lib\site-packages\django\forms\forms.py", line 153, in errors
    self.full_clean()
  File "C:\Users\Samo\AppData\Local\Programs\Python\Python35\lib\site-packages\django\forms\forms.py", line 362, in full_clean
    self._clean_fields()
  File "C:\Users\Samo\AppData\Local\Programs\Python\Python35\lib\site-packages\django\forms\forms.py", line 383, in _clean_fields
    value = getattr(self, 'clean_%s' % name)()
  File "C:\Users\Samo\Desktop\projekt-tomo\projekt-tomo\web\users\admin.py", line 18, in clean_username
    raise forms.ValidationError(self.error_messages['duplicate_username'])
KeyError: 'duplicate_username'
Internal Server Error: /admin/users/user/add/
Traceback (most recent call last):
  File "C:\Users\Samo\AppData\Local\Programs\Python\Python35\lib\site-packages\django\core\handlers\base.py", line 149, in get_response
    response = self.process_exception_by_middleware(e, request)
  File "C:\Users\Samo\AppData\Local\Programs\Python\Python35\lib\site-packages\django\core\handlers\base.py", line 147, in get_response
    response = wrapped_callback(request, *callback_args, **callback_kwargs)
  File "C:\Users\Samo\AppData\Local\Programs\Python\Python35\lib\site-packages\django\contrib\admin\options.py", line 541, in wrapper
    return self.admin_site.admin_view(view)(*args, **kwargs)
  File "C:\Users\Samo\AppData\Local\Programs\Python\Python35\lib\site-packages\django\utils\decorators.py", line 149, in _wrapped_view
    response = view_func(request, *args, **kwargs)
  File "C:\Users\Samo\AppData\Local\Programs\Python\Python35\lib\site-packages\django\views\decorators\cache.py", line 57, in _wrapped_view_func
    response = view_func(request, *args, **kwargs)
  File "C:\Users\Samo\AppData\Local\Programs\Python\Python35\lib\site-packages\django\contrib\admin\sites.py", line 244, in inner
    return view(request, *args, **kwargs)
  File "C:\Users\Samo\AppData\Local\Programs\Python\Python35\lib\site-packages\django\utils\decorators.py", line 67, in _wrapper
    return bound_func(*args, **kwargs)
  File "C:\Users\Samo\AppData\Local\Programs\Python\Python35\lib\site-packages\django\views\decorators\debug.py", line 76, in sensitive_post_parameters_wrapper
    return view(request, *args, **kwargs)
  File "C:\Users\Samo\AppData\Local\Programs\Python\Python35\lib\site-packages\django\utils\decorators.py", line 63, in bound_func
    return func.__get__(self, type(self))(*args2, **kwargs2)
  File "C:\Users\Samo\AppData\Local\Programs\Python\Python35\lib\site-packages\django\utils\decorators.py", line 67, in _wrapper
    return bound_func(*args, **kwargs)
  File "C:\Users\Samo\AppData\Local\Programs\Python\Python35\lib\site-packages\django\utils\decorators.py", line 149, in _wrapped_view
    response = view_func(request, *args, **kwargs)
  File "C:\Users\Samo\AppData\Local\Programs\Python\Python35\lib\site-packages\django\utils\decorators.py", line 63, in bound_func
    return func.__get__(self, type(self))(*args2, **kwargs2)
  File "C:\Users\Samo\AppData\Local\Programs\Python\Python35\lib\contextlib.py", line 30, in inner
    return func(*args, **kwds)
  File "C:\Users\Samo\AppData\Local\Programs\Python\Python35\lib\site-packages\django\contrib\auth\admin.py", line 128, in add_view
    extra_context)
  File "C:\Users\Samo\AppData\Local\Programs\Python\Python35\lib\site-packages\django\contrib\admin\options.py", line 1437, in add_view
    return self.changeform_view(request, None, form_url, extra_context)
  File "C:\Users\Samo\AppData\Local\Programs\Python\Python35\lib\site-packages\django\utils\decorators.py", line 67, in _wrapper
    return bound_func(*args, **kwargs)
  File "C:\Users\Samo\AppData\Local\Programs\Python\Python35\lib\site-packages\django\utils\decorators.py", line 149, in _wrapped_view
    response = view_func(request, *args, **kwargs)
  File "C:\Users\Samo\AppData\Local\Programs\Python\Python35\lib\site-packages\django\utils\decorators.py", line 63, in bound_func
    return func.__get__(self, type(self))(*args2, **kwargs2)
  File "C:\Users\Samo\AppData\Local\Programs\Python\Python35\lib\contextlib.py", line 30, in inner
    return func(*args, **kwds)
  File "C:\Users\Samo\AppData\Local\Programs\Python\Python35\lib\site-packages\django\contrib\admin\options.py", line 1370, in changeform_view
    if form.is_valid():
  File "C:\Users\Samo\AppData\Local\Programs\Python\Python35\lib\site-packages\django\forms\forms.py", line 161, in is_valid
    return self.is_bound and not self.errors
  File "C:\Users\Samo\AppData\Local\Programs\Python\Python35\lib\site-packages\django\forms\forms.py", line 153, in errors
    self.full_clean()
  File "C:\Users\Samo\AppData\Local\Programs\Python\Python35\lib\site-packages\django\forms\forms.py", line 362, in full_clean
    self._clean_fields()
  File "C:\Users\Samo\AppData\Local\Programs\Python\Python35\lib\site-packages\django\forms\forms.py", line 383, in _clean_fields
    value = getattr(self, 'clean_%s' % name)()
  File "C:\Users\Samo\Desktop\projekt-tomo\projekt-tomo\web\users\admin.py", line 18, in clean_username
    raise forms.ValidationError(self.error_messages['duplicate_username'])
KeyError: 'duplicate_username'
Internal Server Error: /admin/users/user/add/
Traceback (most recent call last):
  File "C:\Users\Samo\AppData\Local\Programs\Python\Python35\lib\site-packages\django\core\handlers\base.py", line 149, in get_response
    response = self.process_exception_by_middleware(e, request)
  File "C:\Users\Samo\AppData\Local\Programs\Python\Python35\lib\site-packages\django\core\handlers\base.py", line 147, in get_response
    response = wrapped_callback(request, *callback_args, **callback_kwargs)
  File "C:\Users\Samo\AppData\Local\Programs\Python\Python35\lib\site-packages\django\contrib\admin\options.py", line 541, in wrapper
    return self.admin_site.admin_view(view)(*args, **kwargs)
  File "C:\Users\Samo\AppData\Local\Programs\Python\Python35\lib\site-packages\django\utils\decorators.py", line 149, in _wrapped_view
    response = view_func(request, *args, **kwargs)
  File "C:\Users\Samo\AppData\Local\Programs\Python\Python35\lib\site-packages\django\views\decorators\cache.py", line 57, in _wrapped_view_func
    response = view_func(request, *args, **kwargs)
  File "C:\Users\Samo\AppData\Local\Programs\Python\Python35\lib\site-packages\django\contrib\admin\sites.py", line 244, in inner
    return view(request, *args, **kwargs)
  File "C:\Users\Samo\AppData\Local\Programs\Python\Python35\lib\site-packages\django\utils\decorators.py", line 67, in _wrapper
    return bound_func(*args, **kwargs)
  File "C:\Users\Samo\AppData\Local\Programs\Python\Python35\lib\site-packages\django\views\decorators\debug.py", line 76, in sensitive_post_parameters_wrapper
    return view(request, *args, **kwargs)
  File "C:\Users\Samo\AppData\Local\Programs\Python\Python35\lib\site-packages\django\utils\decorators.py", line 63, in bound_func
    return func.__get__(self, type(self))(*args2, **kwargs2)
  File "C:\Users\Samo\AppData\Local\Programs\Python\Python35\lib\site-packages\django\utils\decorators.py", line 67, in _wrapper
    return bound_func(*args, **kwargs)
  File "C:\Users\Samo\AppData\Local\Programs\Python\Python35\lib\site-packages\django\utils\decorators.py", line 149, in _wrapped_view
    response = view_func(request, *args, **kwargs)
  File "C:\Users\Samo\AppData\Local\Programs\Python\Python35\lib\site-packages\django\utils\decorators.py", line 63, in bound_func
    return func.__get__(self, type(self))(*args2, **kwargs2)
  File "C:\Users\Samo\AppData\Local\Programs\Python\Python35\lib\contextlib.py", line 30, in inner
    return func(*args, **kwds)
  File "C:\Users\Samo\AppData\Local\Programs\Python\Python35\lib\site-packages\django\contrib\auth\admin.py", line 128, in add_view
    extra_context)
  File "C:\Users\Samo\AppData\Local\Programs\Python\Python35\lib\site-packages\django\contrib\admin\options.py", line 1437, in add_view
    return self.changeform_view(request, None, form_url, extra_context)
  File "C:\Users\Samo\AppData\Local\Programs\Python\Python35\lib\site-packages\django\utils\decorators.py", line 67, in _wrapper
    return bound_func(*args, **kwargs)
  File "C:\Users\Samo\AppData\Local\Programs\Python\Python35\lib\site-packages\django\utils\decorators.py", line 149, in _wrapped_view
    response = view_func(request, *args, **kwargs)
  File "C:\Users\Samo\AppData\Local\Programs\Python\Python35\lib\site-packages\django\utils\decorators.py", line 63, in bound_func
    return func.__get__(self, type(self))(*args2, **kwargs2)
  File "C:\Users\Samo\AppData\Local\Programs\Python\Python35\lib\contextlib.py", line 30, in inner
    return func(*args, **kwds)
  File "C:\Users\Samo\AppData\Local\Programs\Python\Python35\lib\site-packages\django\contrib\admin\options.py", line 1370, in changeform_view
    if form.is_valid():
  File "C:\Users\Samo\AppData\Local\Programs\Python\Python35\lib\site-packages\django\forms\forms.py", line 161, in is_valid
    return self.is_bound and not self.errors
  File "C:\Users\Samo\AppData\Local\Programs\Python\Python35\lib\site-packages\django\forms\forms.py", line 153, in errors
    self.full_clean()
  File "C:\Users\Samo\AppData\Local\Programs\Python\Python35\lib\site-packages\django\forms\forms.py", line 362, in full_clean
    self._clean_fields()
  File "C:\Users\Samo\AppData\Local\Programs\Python\Python35\lib\site-packages\django\forms\forms.py", line 383, in _clean_fields
    value = getattr(self, 'clean_%s' % name)()
  File "C:\Users\Samo\Desktop\projekt-tomo\projekt-tomo\web\users\admin.py", line 18, in clean_username
    raise forms.ValidationError(self.error_messages['duplicate_username'])
KeyError: 'duplicate_username'
Not Found: /favicon.ico
Not Found: /avtomobili/
Not Found: /favicon.ico
Not Found: /avtomobili/
Internal Server Error: /problem_set/81/
Traceback (most recent call last):
  File "C:\Users\Samo\AppData\Local\Programs\Python\Python35\lib\site-packages\django\db\backends\utils.py", line 64, in execute
    return self.cursor.execute(sql, params)
psycopg2.ProgrammingError: column problems_problem.verify_attempt_tokens does not exist
LINE 1: ...."problem_set_id", "problems_problem"."language", "problems_...
                                                             ^


The above exception was the direct cause of the following exception:

Traceback (most recent call last):
  File "C:\Users\Samo\AppData\Local\Programs\Python\Python35\lib\site-packages\django\core\handlers\base.py", line 149, in get_response
    response = self.process_exception_by_middleware(e, request)
  File "C:\Users\Samo\AppData\Local\Programs\Python\Python35\lib\site-packages\django\core\handlers\base.py", line 147, in get_response
    response = wrapped_callback(request, *callback_args, **callback_kwargs)
  File "C:\Users\Samo\AppData\Local\Programs\Python\Python35\lib\site-packages\django\contrib\auth\decorators.py", line 23, in _wrapped_view
    return view_func(request, *args, **kwargs)
  File "C:\Users\Samo\Desktop\projekt-tomo\projekt-tomo\web\courses\views.py", line 61, in problem_set_detail
    'show_teacher_forms': request.user.can_edit_problem_set(problem_set),
  File "C:\Users\Samo\AppData\Local\Programs\Python\Python35\lib\site-packages\django\shortcuts.py", line 67, in render
    template_name, context, request=request, using=using)
  File "C:\Users\Samo\AppData\Local\Programs\Python\Python35\lib\site-packages\django\template\loader.py", line 97, in render_to_string
    return template.render(context, request)
  File "C:\Users\Samo\AppData\Local\Programs\Python\Python35\lib\site-packages\django\template\backends\django.py", line 95, in render
    return self.template.render(context)
  File "C:\Users\Samo\AppData\Local\Programs\Python\Python35\lib\site-packages\django\template\base.py", line 206, in render
    return self._render(context)
  File "C:\Users\Samo\AppData\Local\Programs\Python\Python35\lib\site-packages\django\test\utils.py", line 92, in instrumented_test_render
    return self.nodelist.render(context)
  File "C:\Users\Samo\AppData\Local\Programs\Python\Python35\lib\site-packages\django\template\base.py", line 992, in render
    bit = node.render_annotated(context)
  File "C:\Users\Samo\AppData\Local\Programs\Python\Python35\lib\site-packages\django\template\base.py", line 959, in render_annotated
    return self.render(context)
  File "C:\Users\Samo\AppData\Local\Programs\Python\Python35\lib\site-packages\django\template\loader_tags.py", line 173, in render
    return compiled_parent._render(context)
  File "C:\Users\Samo\AppData\Local\Programs\Python\Python35\lib\site-packages\django\test\utils.py", line 92, in instrumented_test_render
    return self.nodelist.render(context)
  File "C:\Users\Samo\AppData\Local\Programs\Python\Python35\lib\site-packages\django\template\base.py", line 992, in render
    bit = node.render_annotated(context)
  File "C:\Users\Samo\AppData\Local\Programs\Python\Python35\lib\site-packages\django\template\base.py", line 959, in render_annotated
    return self.render(context)
  File "C:\Users\Samo\AppData\Local\Programs\Python\Python35\lib\site-packages\django\template\loader_tags.py", line 69, in render
    result = block.nodelist.render(context)
  File "C:\Users\Samo\AppData\Local\Programs\Python\Python35\lib\site-packages\django\template\base.py", line 992, in render
    bit = node.render_annotated(context)
  File "C:\Users\Samo\AppData\Local\Programs\Python\Python35\lib\site-packages\django\template\base.py", line 959, in render_annotated
    return self.render(context)
  File "C:\Users\Samo\AppData\Local\Programs\Python\Python35\lib\site-packages\django\template\loader_tags.py", line 69, in render
    result = block.nodelist.render(context)
  File "C:\Users\Samo\AppData\Local\Programs\Python\Python35\lib\site-packages\django\template\base.py", line 992, in render
    bit = node.render_annotated(context)
  File "C:\Users\Samo\AppData\Local\Programs\Python\Python35\lib\site-packages\django\template\base.py", line 959, in render_annotated
    return self.render(context)
  File "C:\Users\Samo\AppData\Local\Programs\Python\Python35\lib\site-packages\django\template\defaulttags.py", line 168, in render
    len_values = len(values)
  File "C:\Users\Samo\AppData\Local\Programs\Python\Python35\lib\site-packages\django\db\models\query.py", line 240, in __len__
    self._fetch_all()
  File "C:\Users\Samo\AppData\Local\Programs\Python\Python35\lib\site-packages\django\db\models\query.py", line 1074, in _fetch_all
    self._result_cache = list(self.iterator())
  File "C:\Users\Samo\AppData\Local\Programs\Python\Python35\lib\site-packages\django\db\models\query.py", line 52, in __iter__
    results = compiler.execute_sql()
  File "C:\Users\Samo\AppData\Local\Programs\Python\Python35\lib\site-packages\django\db\models\sql\compiler.py", line 848, in execute_sql
    cursor.execute(sql, params)
  File "C:\Users\Samo\AppData\Local\Programs\Python\Python35\lib\site-packages\debug_toolbar\panels\sql\tracking.py", line 159, in execute
    return self._record(self.cursor.execute, sql, params)
  File "C:\Users\Samo\AppData\Local\Programs\Python\Python35\lib\site-packages\debug_toolbar\panels\sql\tracking.py", line 101, in _record
    return method(sql, params)
  File "C:\Users\Samo\AppData\Local\Programs\Python\Python35\lib\site-packages\django\db\backends\utils.py", line 79, in execute
    return super(CursorDebugWrapper, self).execute(sql, params)
  File "C:\Users\Samo\AppData\Local\Programs\Python\Python35\lib\site-packages\django\db\backends\utils.py", line 64, in execute
    return self.cursor.execute(sql, params)
  File "C:\Users\Samo\AppData\Local\Programs\Python\Python35\lib\site-packages\django\db\utils.py", line 95, in __exit__
    six.reraise(dj_exc_type, dj_exc_value, traceback)
  File "C:\Users\Samo\AppData\Local\Programs\Python\Python35\lib\site-packages\django\utils\six.py", line 685, in reraise
    raise value.with_traceback(tb)
  File "C:\Users\Samo\AppData\Local\Programs\Python\Python35\lib\site-packages\django\db\backends\utils.py", line 64, in execute
    return self.cursor.execute(sql, params)
django.db.utils.ProgrammingError: column problems_problem.verify_attempt_tokens does not exist
LINE 1: ...."problem_set_id", "problems_problem"."language", "problems_...
                                                             ^

Internal Server Error: /problem_set/94/
Traceback (most recent call last):
  File "C:\Users\Samo\AppData\Local\Programs\Python\Python35\lib\site-packages\django\db\backends\utils.py", line 64, in execute
    return self.cursor.execute(sql, params)
psycopg2.ProgrammingError: column problems_problem.verify_attempt_tokens does not exist
LINE 1: ...."problem_set_id", "problems_problem"."language", "problems_...
                                                             ^


The above exception was the direct cause of the following exception:

Traceback (most recent call last):
  File "C:\Users\Samo\AppData\Local\Programs\Python\Python35\lib\site-packages\django\core\handlers\base.py", line 149, in get_response
    response = self.process_exception_by_middleware(e, request)
  File "C:\Users\Samo\AppData\Local\Programs\Python\Python35\lib\site-packages\django\core\handlers\base.py", line 147, in get_response
    response = wrapped_callback(request, *callback_args, **callback_kwargs)
  File "C:\Users\Samo\AppData\Local\Programs\Python\Python35\lib\site-packages\django\contrib\auth\decorators.py", line 23, in _wrapped_view
    return view_func(request, *args, **kwargs)
  File "C:\Users\Samo\Desktop\projekt-tomo\projekt-tomo\web\courses\views.py", line 61, in problem_set_detail
    'show_teacher_forms': request.user.can_edit_problem_set(problem_set),
  File "C:\Users\Samo\AppData\Local\Programs\Python\Python35\lib\site-packages\django\shortcuts.py", line 67, in render
    template_name, context, request=request, using=using)
  File "C:\Users\Samo\AppData\Local\Programs\Python\Python35\lib\site-packages\django\template\loader.py", line 97, in render_to_string
    return template.render(context, request)
  File "C:\Users\Samo\AppData\Local\Programs\Python\Python35\lib\site-packages\django\template\backends\django.py", line 95, in render
    return self.template.render(context)
  File "C:\Users\Samo\AppData\Local\Programs\Python\Python35\lib\site-packages\django\template\base.py", line 206, in render
    return self._render(context)
  File "C:\Users\Samo\AppData\Local\Programs\Python\Python35\lib\site-packages\django\test\utils.py", line 92, in instrumented_test_render
    return self.nodelist.render(context)
  File "C:\Users\Samo\AppData\Local\Programs\Python\Python35\lib\site-packages\django\template\base.py", line 992, in render
    bit = node.render_annotated(context)
  File "C:\Users\Samo\AppData\Local\Programs\Python\Python35\lib\site-packages\django\template\base.py", line 959, in render_annotated
    return self.render(context)
  File "C:\Users\Samo\AppData\Local\Programs\Python\Python35\lib\site-packages\django\template\loader_tags.py", line 173, in render
    return compiled_parent._render(context)
  File "C:\Users\Samo\AppData\Local\Programs\Python\Python35\lib\site-packages\django\test\utils.py", line 92, in instrumented_test_render
    return self.nodelist.render(context)
  File "C:\Users\Samo\AppData\Local\Programs\Python\Python35\lib\site-packages\django\template\base.py", line 992, in render
    bit = node.render_annotated(context)
  File "C:\Users\Samo\AppData\Local\Programs\Python\Python35\lib\site-packages\django\template\base.py", line 959, in render_annotated
    return self.render(context)
  File "C:\Users\Samo\AppData\Local\Programs\Python\Python35\lib\site-packages\django\template\loader_tags.py", line 69, in render
    result = block.nodelist.render(context)
  File "C:\Users\Samo\AppData\Local\Programs\Python\Python35\lib\site-packages\django\template\base.py", line 992, in render
    bit = node.render_annotated(context)
  File "C:\Users\Samo\AppData\Local\Programs\Python\Python35\lib\site-packages\django\template\base.py", line 959, in render_annotated
    return self.render(context)
  File "C:\Users\Samo\AppData\Local\Programs\Python\Python35\lib\site-packages\django\template\loader_tags.py", line 69, in render
    result = block.nodelist.render(context)
  File "C:\Users\Samo\AppData\Local\Programs\Python\Python35\lib\site-packages\django\template\base.py", line 992, in render
    bit = node.render_annotated(context)
  File "C:\Users\Samo\AppData\Local\Programs\Python\Python35\lib\site-packages\django\template\base.py", line 959, in render_annotated
    return self.render(context)
  File "C:\Users\Samo\AppData\Local\Programs\Python\Python35\lib\site-packages\django\template\defaulttags.py", line 168, in render
    len_values = len(values)
  File "C:\Users\Samo\AppData\Local\Programs\Python\Python35\lib\site-packages\django\db\models\query.py", line 240, in __len__
    self._fetch_all()
  File "C:\Users\Samo\AppData\Local\Programs\Python\Python35\lib\site-packages\django\db\models\query.py", line 1074, in _fetch_all
    self._result_cache = list(self.iterator())
  File "C:\Users\Samo\AppData\Local\Programs\Python\Python35\lib\site-packages\django\db\models\query.py", line 52, in __iter__
    results = compiler.execute_sql()
  File "C:\Users\Samo\AppData\Local\Programs\Python\Python35\lib\site-packages\django\db\models\sql\compiler.py", line 848, in execute_sql
    cursor.execute(sql, params)
  File "C:\Users\Samo\AppData\Local\Programs\Python\Python35\lib\site-packages\debug_toolbar\panels\sql\tracking.py", line 159, in execute
    return self._record(self.cursor.execute, sql, params)
  File "C:\Users\Samo\AppData\Local\Programs\Python\Python35\lib\site-packages\debug_toolbar\panels\sql\tracking.py", line 101, in _record
    return method(sql, params)
  File "C:\Users\Samo\AppData\Local\Programs\Python\Python35\lib\site-packages\django\db\backends\utils.py", line 79, in execute
    return super(CursorDebugWrapper, self).execute(sql, params)
  File "C:\Users\Samo\AppData\Local\Programs\Python\Python35\lib\site-packages\django\db\backends\utils.py", line 64, in execute
    return self.cursor.execute(sql, params)
  File "C:\Users\Samo\AppData\Local\Programs\Python\Python35\lib\site-packages\django\db\utils.py", line 95, in __exit__
    six.reraise(dj_exc_type, dj_exc_value, traceback)
  File "C:\Users\Samo\AppData\Local\Programs\Python\Python35\lib\site-packages\django\utils\six.py", line 685, in reraise
    raise value.with_traceback(tb)
  File "C:\Users\Samo\AppData\Local\Programs\Python\Python35\lib\site-packages\django\db\backends\utils.py", line 64, in execute
    return self.cursor.execute(sql, params)
django.db.utils.ProgrammingError: column problems_problem.verify_attempt_tokens does not exist
LINE 1: ...."problem_set_id", "problems_problem"."language", "problems_...
                                                             ^

Internal Server Error: /course/17/progress/503/
Traceback (most recent call last):
  File "C:\Users\Samo\AppData\Local\Programs\Python\Python35\lib\site-packages\django\db\backends\utils.py", line 64, in execute
    return self.cursor.execute(sql, params)
psycopg2.ProgrammingError: column attempts_attempt.submission_date does not exist
LINE 1: ..._attempt"."valid", "attempts_attempt"."feedback", "attempts_...
                                                             ^


The above exception was the direct cause of the following exception:

Traceback (most recent call last):
  File "C:\Users\Samo\AppData\Local\Programs\Python\Python35\lib\site-packages\django\core\handlers\base.py", line 149, in get_response
    response = self.process_exception_by_middleware(e, request)
  File "C:\Users\Samo\AppData\Local\Programs\Python\Python35\lib\site-packages\django\core\handlers\base.py", line 147, in get_response
    response = wrapped_callback(request, *callback_args, **callback_kwargs)
  File "C:\Users\Samo\AppData\Local\Programs\Python\Python35\lib\site-packages\django\contrib\auth\decorators.py", line 23, in _wrapped_view
    return view_func(request, *args, **kwargs)
  File "C:\Users\Samo\Desktop\projekt-tomo\projekt-tomo\web\courses\views.py", line 222, in course_progress
    'course_attempts': course.user_attempts(user)
  File "C:\Users\Samo\Desktop\projekt-tomo\projekt-tomo\web\courses\models.py", line 47, in user_attempts
    for attempt in user.attempts.filter(part__problem__problem_set__course=self):
  File "C:\Users\Samo\AppData\Local\Programs\Python\Python35\lib\site-packages\django\db\models\query.py", line 258, in __iter__
    self._fetch_all()
  File "C:\Users\Samo\AppData\Local\Programs\Python\Python35\lib\site-packages\django\db\models\query.py", line 1074, in _fetch_all
    self._result_cache = list(self.iterator())
  File "C:\Users\Samo\AppData\Local\Programs\Python\Python35\lib\site-packages\django\db\models\query.py", line 52, in __iter__
    results = compiler.execute_sql()
  File "C:\Users\Samo\AppData\Local\Programs\Python\Python35\lib\site-packages\django\db\models\sql\compiler.py", line 848, in execute_sql
    cursor.execute(sql, params)
  File "C:\Users\Samo\AppData\Local\Programs\Python\Python35\lib\site-packages\debug_toolbar\panels\sql\tracking.py", line 159, in execute
    return self._record(self.cursor.execute, sql, params)
  File "C:\Users\Samo\AppData\Local\Programs\Python\Python35\lib\site-packages\debug_toolbar\panels\sql\tracking.py", line 101, in _record
    return method(sql, params)
  File "C:\Users\Samo\AppData\Local\Programs\Python\Python35\lib\site-packages\django\db\backends\utils.py", line 79, in execute
    return super(CursorDebugWrapper, self).execute(sql, params)
  File "C:\Users\Samo\AppData\Local\Programs\Python\Python35\lib\site-packages\django\db\backends\utils.py", line 64, in execute
    return self.cursor.execute(sql, params)
  File "C:\Users\Samo\AppData\Local\Programs\Python\Python35\lib\site-packages\django\db\utils.py", line 95, in __exit__
    six.reraise(dj_exc_type, dj_exc_value, traceback)
  File "C:\Users\Samo\AppData\Local\Programs\Python\Python35\lib\site-packages\django\utils\six.py", line 685, in reraise
    raise value.with_traceback(tb)
  File "C:\Users\Samo\AppData\Local\Programs\Python\Python35\lib\site-packages\django\db\backends\utils.py", line 64, in execute
    return self.cursor.execute(sql, params)
django.db.utils.ProgrammingError: column attempts_attempt.submission_date does not exist
LINE 1: ..._attempt"."valid", "attempts_attempt"."feedback", "attempts_...
                                                             ^

Not Found: /avtomobili/
Internal Server Error: /course/17/progress/454/
Traceback (most recent call last):
  File "C:\Users\Samo\AppData\Local\Programs\Python\Python35\lib\site-packages\django\db\backends\utils.py", line 64, in execute
    return self.cursor.execute(sql, params)
psycopg2.ProgrammingError: column attempts_attempt.submission_date does not exist
LINE 1: ..._attempt"."valid", "attempts_attempt"."feedback", "attempts_...
                                                             ^


The above exception was the direct cause of the following exception:

Traceback (most recent call last):
  File "C:\Users\Samo\AppData\Local\Programs\Python\Python35\lib\site-packages\django\core\handlers\base.py", line 149, in get_response
    response = self.process_exception_by_middleware(e, request)
  File "C:\Users\Samo\AppData\Local\Programs\Python\Python35\lib\site-packages\django\core\handlers\base.py", line 147, in get_response
    response = wrapped_callback(request, *callback_args, **callback_kwargs)
  File "C:\Users\Samo\AppData\Local\Programs\Python\Python35\lib\site-packages\django\contrib\auth\decorators.py", line 23, in _wrapped_view
    return view_func(request, *args, **kwargs)
  File "C:\Users\Samo\Desktop\projekt-tomo\projekt-tomo\web\courses\views.py", line 222, in course_progress
    'course_attempts': course.user_attempts(user)
  File "C:\Users\Samo\Desktop\projekt-tomo\projekt-tomo\web\courses\models.py", line 47, in user_attempts
    for attempt in user.attempts.filter(part__problem__problem_set__course=self):
  File "C:\Users\Samo\AppData\Local\Programs\Python\Python35\lib\site-packages\django\db\models\query.py", line 258, in __iter__
    self._fetch_all()
  File "C:\Users\Samo\AppData\Local\Programs\Python\Python35\lib\site-packages\django\db\models\query.py", line 1074, in _fetch_all
    self._result_cache = list(self.iterator())
  File "C:\Users\Samo\AppData\Local\Programs\Python\Python35\lib\site-packages\django\db\models\query.py", line 52, in __iter__
    results = compiler.execute_sql()
  File "C:\Users\Samo\AppData\Local\Programs\Python\Python35\lib\site-packages\django\db\models\sql\compiler.py", line 848, in execute_sql
    cursor.execute(sql, params)
  File "C:\Users\Samo\AppData\Local\Programs\Python\Python35\lib\site-packages\debug_toolbar\panels\sql\tracking.py", line 159, in execute
    return self._record(self.cursor.execute, sql, params)
  File "C:\Users\Samo\AppData\Local\Programs\Python\Python35\lib\site-packages\debug_toolbar\panels\sql\tracking.py", line 101, in _record
    return method(sql, params)
  File "C:\Users\Samo\AppData\Local\Programs\Python\Python35\lib\site-packages\django\db\backends\utils.py", line 79, in execute
    return super(CursorDebugWrapper, self).execute(sql, params)
  File "C:\Users\Samo\AppData\Local\Programs\Python\Python35\lib\site-packages\django\db\backends\utils.py", line 64, in execute
    return self.cursor.execute(sql, params)
  File "C:\Users\Samo\AppData\Local\Programs\Python\Python35\lib\site-packages\django\db\utils.py", line 95, in __exit__
    six.reraise(dj_exc_type, dj_exc_value, traceback)
  File "C:\Users\Samo\AppData\Local\Programs\Python\Python35\lib\site-packages\django\utils\six.py", line 685, in reraise
    raise value.with_traceback(tb)
  File "C:\Users\Samo\AppData\Local\Programs\Python\Python35\lib\site-packages\django\db\backends\utils.py", line 64, in execute
    return self.cursor.execute(sql, params)
django.db.utils.ProgrammingError: column attempts_attempt.submission_date does not exist
LINE 1: ..._attempt"."valid", "attempts_attempt"."feedback", "attempts_...
                                                             ^

Not Found: /problem_set/81/{% url 'all_solutions_to_part' part.id}
Not Found: /problem_set/81/{% url 'all_solutions_to_part' part.id}
Not Found: /problem_set/81/{% url 'all_solutions_to_part' part.id}
Not Found: /problem_set/81/{% url 'all_solutions_to_part' part.id}
Not Found: /problem_set/81/{% url 'all_solutions_to_part' part.id}
Not Found: /problem_set/81/{% url 'all_solutions_to_part' part.id}
Not Found: /problem_set/81/{% url 'all_solutions_to_part' part.id}
Not Found: /problem_set/81/{% url 'all_solutions_to_part' part.id}
Not Found: /problem_set/81/{% url 'all_solutions_to_part' part.id}
Not Found: /problem_set/81/{% url 'all_solutions_to_part' part.id}
Not Found: /problem_set/81/{% url 'all_solutions_to_part' part.id}
Not Found: /problem_set/81/{% url 'all_solutions_to_part' part.id}
Not Found: /problem_set/81/{% url 'all_solutions_to_part' part.id}
Not Found: /problem_set/81/{% url 'all_solutions_to_part' part.id}
Internal Server Error: /problems/view_all/907
Traceback (most recent call last):
  File "C:\Users\Samo\AppData\Local\Programs\Python\Python35\lib\site-packages\django\core\handlers\base.py", line 149, in get_response
    response = self.process_exception_by_middleware(e, request)
  File "C:\Users\Samo\AppData\Local\Programs\Python\Python35\lib\site-packages\django\core\handlers\base.py", line 147, in get_response
    response = wrapped_callback(request, *callback_args, **callback_kwargs)
  File "C:\Users\Samo\AppData\Local\Programs\Python\Python35\lib\site-packages\django\contrib\auth\decorators.py", line 23, in _wrapped_view
    return view_func(request, *args, **kwargs)
  File "C:\Users\Samo\Desktop\projekt-tomo\projekt-tomo\web\problems\views.py", line 163, in all_solutions_to_part
    attempts = Attempts.objects.filter(part__id=part_pk)
NameError: name 'Attempts' is not defined
Not Found: /problems//view_all/907
Internal Server Error: /problems/view_all/907
Traceback (most recent call last):
  File "C:\Users\Samo\AppData\Local\Programs\Python\Python35\lib\site-packages\django\core\handlers\base.py", line 149, in get_response
    response = self.process_exception_by_middleware(e, request)
  File "C:\Users\Samo\AppData\Local\Programs\Python\Python35\lib\site-packages\django\core\handlers\base.py", line 147, in get_response
    response = wrapped_callback(request, *callback_args, **callback_kwargs)
  File "C:\Users\Samo\AppData\Local\Programs\Python\Python35\lib\site-packages\django\contrib\auth\decorators.py", line 23, in _wrapped_view
    return view_func(request, *args, **kwargs)
  File "C:\Users\Samo\Desktop\projekt-tomo\projekt-tomo\web\problems\views.py", line 163, in all_solutions_to_part
    part = get_object_or_404(Part, pk=part_pk)
NameError: name 'Part' is not defined
Internal Server Error: /problems/view_all/907
Traceback (most recent call last):
  File "C:\Users\Samo\AppData\Local\Programs\Python\Python35\lib\site-packages\django\core\handlers\base.py", line 149, in get_response
    response = self.process_exception_by_middleware(e, request)
  File "C:\Users\Samo\AppData\Local\Programs\Python\Python35\lib\site-packages\django\core\handlers\base.py", line 147, in get_response
    response = wrapped_callback(request, *callback_args, **callback_kwargs)
  File "C:\Users\Samo\AppData\Local\Programs\Python\Python35\lib\site-packages\django\contrib\auth\decorators.py", line 23, in _wrapped_view
    return view_func(request, *args, **kwargs)
  File "C:\Users\Samo\Desktop\projekt-tomo\projekt-tomo\web\problems\views.py", line 164, in all_solutions_to_part
    return HttpResponse('DELA' + str(part_pk) + ' ' + str(len(attempts)))
NameError: name 'attempts' is not defined
Internal Server Error: /problems/view_all/907
Traceback (most recent call last):
  File "C:\Users\Samo\AppData\Local\Programs\Python\Python35\lib\site-packages\django\core\handlers\base.py", line 149, in get_response
    response = self.process_exception_by_middleware(e, request)
  File "C:\Users\Samo\AppData\Local\Programs\Python\Python35\lib\site-packages\django\core\handlers\base.py", line 147, in get_response
    response = wrapped_callback(request, *callback_args, **callback_kwargs)
  File "C:\Users\Samo\AppData\Local\Programs\Python\Python35\lib\site-packages\django\contrib\auth\decorators.py", line 23, in _wrapped_view
    return view_func(request, *args, **kwargs)
  File "C:\Users\Samo\Desktop\projekt-tomo\projekt-tomo\web\problems\views.py", line 167, in all_solutions_to_part
    return HttpResponse('DELA' + str(part_pk) + ' ' + str(course_pk) + ' ' + len(students))
TypeError: Can't convert 'int' object to str implicitly
Internal Server Error: /problems/view_all/907
Traceback (most recent call last):
  File "C:\Users\Samo\AppData\Local\Programs\Python\Python35\lib\site-packages\django\core\handlers\base.py", line 149, in get_response
    response = self.process_exception_by_middleware(e, request)
  File "C:\Users\Samo\AppData\Local\Programs\Python\Python35\lib\site-packages\django\core\handlers\base.py", line 147, in get_response
    response = wrapped_callback(request, *callback_args, **callback_kwargs)
  File "C:\Users\Samo\AppData\Local\Programs\Python\Python35\lib\site-packages\django\contrib\auth\decorators.py", line 23, in _wrapped_view
    return view_func(request, *args, **kwargs)
  File "C:\Users\Samo\Desktop\projekt-tomo\projekt-tomo\web\problems\views.py", line 166, in all_solutions_to_part
    problem = get_object_or_404(Problem, pk=part.problem)
  File "C:\Users\Samo\AppData\Local\Programs\Python\Python35\lib\site-packages\django\shortcuts.py", line 155, in get_object_or_404
    return queryset.get(*args, **kwargs)
  File "C:\Users\Samo\AppData\Local\Programs\Python\Python35\lib\site-packages\django\db\models\query.py", line 378, in get
    clone = self.filter(*args, **kwargs)
  File "C:\Users\Samo\AppData\Local\Programs\Python\Python35\lib\site-packages\django\db\models\query.py", line 790, in filter
    return self._filter_or_exclude(False, *args, **kwargs)
  File "C:\Users\Samo\AppData\Local\Programs\Python\Python35\lib\site-packages\django\db\models\query.py", line 808, in _filter_or_exclude
    clone.query.add_q(Q(*args, **kwargs))
  File "C:\Users\Samo\AppData\Local\Programs\Python\Python35\lib\site-packages\django\db\models\sql\query.py", line 1243, in add_q
    clause, _ = self._add_q(q_object, self.used_aliases)
  File "C:\Users\Samo\AppData\Local\Programs\Python\Python35\lib\site-packages\django\db\models\sql\query.py", line 1269, in _add_q
    allow_joins=allow_joins, split_subq=split_subq,
  File "C:\Users\Samo\AppData\Local\Programs\Python\Python35\lib\site-packages\django\db\models\sql\query.py", line 1203, in build_filter
    condition = self.build_lookup(lookups, col, value)
  File "C:\Users\Samo\AppData\Local\Programs\Python\Python35\lib\site-packages\django\db\models\sql\query.py", line 1099, in build_lookup
    return final_lookup(lhs, rhs)
  File "C:\Users\Samo\AppData\Local\Programs\Python\Python35\lib\site-packages\django\db\models\lookups.py", line 19, in __init__
    self.rhs = self.get_prep_lookup()
  File "C:\Users\Samo\AppData\Local\Programs\Python\Python35\lib\site-packages\django\db\models\lookups.py", line 57, in get_prep_lookup
    return self.lhs.output_field.get_prep_lookup(self.lookup_name, self.rhs)
  File "C:\Users\Samo\AppData\Local\Programs\Python\Python35\lib\site-packages\django\db\models\fields\__init__.py", line 744, in get_prep_lookup
    return self.get_prep_value(value)
  File "C:\Users\Samo\AppData\Local\Programs\Python\Python35\lib\site-packages\django\db\models\fields\__init__.py", line 976, in get_prep_value
    return int(value)
TypeError: int() argument must be a string, a bytes-like object or a number, not 'Problem'
Internal Server Error: /problems/view_all/907
Traceback (most recent call last):
  File "C:\Users\Samo\AppData\Local\Programs\Python\Python35\lib\site-packages\django\core\handlers\base.py", line 149, in get_response
    response = self.process_exception_by_middleware(e, request)
  File "C:\Users\Samo\AppData\Local\Programs\Python\Python35\lib\site-packages\django\core\handlers\base.py", line 147, in get_response
    response = wrapped_callback(request, *callback_args, **callback_kwargs)
  File "C:\Users\Samo\AppData\Local\Programs\Python\Python35\lib\site-packages\django\contrib\auth\decorators.py", line 23, in _wrapped_view
    return view_func(request, *args, **kwargs)
  File "C:\Users\Samo\Desktop\projekt-tomo\projekt-tomo\web\problems\views.py", line 166, in all_solutions_to_part
    problem = get_object_or_404(Problem, pk=part.problem)
  File "C:\Users\Samo\AppData\Local\Programs\Python\Python35\lib\site-packages\django\shortcuts.py", line 155, in get_object_or_404
    return queryset.get(*args, **kwargs)
  File "C:\Users\Samo\AppData\Local\Programs\Python\Python35\lib\site-packages\django\db\models\query.py", line 378, in get
    clone = self.filter(*args, **kwargs)
  File "C:\Users\Samo\AppData\Local\Programs\Python\Python35\lib\site-packages\django\db\models\query.py", line 790, in filter
    return self._filter_or_exclude(False, *args, **kwargs)
  File "C:\Users\Samo\AppData\Local\Programs\Python\Python35\lib\site-packages\django\db\models\query.py", line 808, in _filter_or_exclude
    clone.query.add_q(Q(*args, **kwargs))
  File "C:\Users\Samo\AppData\Local\Programs\Python\Python35\lib\site-packages\django\db\models\sql\query.py", line 1243, in add_q
    clause, _ = self._add_q(q_object, self.used_aliases)
  File "C:\Users\Samo\AppData\Local\Programs\Python\Python35\lib\site-packages\django\db\models\sql\query.py", line 1269, in _add_q
    allow_joins=allow_joins, split_subq=split_subq,
  File "C:\Users\Samo\AppData\Local\Programs\Python\Python35\lib\site-packages\django\db\models\sql\query.py", line 1203, in build_filter
    condition = self.build_lookup(lookups, col, value)
  File "C:\Users\Samo\AppData\Local\Programs\Python\Python35\lib\site-packages\django\db\models\sql\query.py", line 1099, in build_lookup
    return final_lookup(lhs, rhs)
  File "C:\Users\Samo\AppData\Local\Programs\Python\Python35\lib\site-packages\django\db\models\lookups.py", line 19, in __init__
    self.rhs = self.get_prep_lookup()
  File "C:\Users\Samo\AppData\Local\Programs\Python\Python35\lib\site-packages\django\db\models\lookups.py", line 57, in get_prep_lookup
    return self.lhs.output_field.get_prep_lookup(self.lookup_name, self.rhs)
  File "C:\Users\Samo\AppData\Local\Programs\Python\Python35\lib\site-packages\django\db\models\fields\__init__.py", line 744, in get_prep_lookup
    return self.get_prep_value(value)
  File "C:\Users\Samo\AppData\Local\Programs\Python\Python35\lib\site-packages\django\db\models\fields\__init__.py", line 976, in get_prep_value
    return int(value)
TypeError: int() argument must be a string, a bytes-like object or a number, not 'Problem'
Internal Server Error: /problems/view_all/907
Traceback (most recent call last):
  File "C:\Users\Samo\AppData\Local\Programs\Python\Python35\lib\site-packages\django\core\handlers\base.py", line 149, in get_response
    response = self.process_exception_by_middleware(e, request)
  File "C:\Users\Samo\AppData\Local\Programs\Python\Python35\lib\site-packages\django\core\handlers\base.py", line 147, in get_response
    response = wrapped_callback(request, *callback_args, **callback_kwargs)
  File "C:\Users\Samo\AppData\Local\Programs\Python\Python35\lib\site-packages\django\contrib\auth\decorators.py", line 23, in _wrapped_view
    return view_func(request, *args, **kwargs)
  File "C:\Users\Samo\Desktop\projekt-tomo\projekt-tomo\web\problems\views.py", line 167, in all_solutions_to_part
    problem_set = get_object_or_404(Problem_set, pk=problem.problem_set.id)
NameError: name 'Problem_set' is not defined
Internal Server Error: /problems/view_all/907
Traceback (most recent call last):
  File "C:\Users\Samo\AppData\Local\Programs\Python\Python35\lib\site-packages\django\core\handlers\base.py", line 149, in get_response
    response = self.process_exception_by_middleware(e, request)
  File "C:\Users\Samo\AppData\Local\Programs\Python\Python35\lib\site-packages\django\core\handlers\base.py", line 147, in get_response
    response = wrapped_callback(request, *callback_args, **callback_kwargs)
  File "C:\Users\Samo\AppData\Local\Programs\Python\Python35\lib\site-packages\django\contrib\auth\decorators.py", line 23, in _wrapped_view
    return view_func(request, *args, **kwargs)
  File "C:\Users\Samo\Desktop\projekt-tomo\projekt-tomo\web\problems\views.py", line 180, in all_solutions_to_part
    + ' ' + str(len(attempts)))
NameError: name 'course_pk' is not defined
Internal Server Error: /problems/view_all/935
Traceback (most recent call last):
  File "C:\Users\Samo\AppData\Local\Programs\Python\Python35\lib\site-packages\django\template\base.py", line 508, in parse
    compile_func = self.tags[command]
KeyError: 'attempt.user'

During handling of the above exception, another exception occurred:

Traceback (most recent call last):
  File "C:\Users\Samo\AppData\Local\Programs\Python\Python35\lib\site-packages\django\core\handlers\base.py", line 149, in get_response
    response = self.process_exception_by_middleware(e, request)
  File "C:\Users\Samo\AppData\Local\Programs\Python\Python35\lib\site-packages\django\core\handlers\base.py", line 147, in get_response
    response = wrapped_callback(request, *callback_args, **callback_kwargs)
  File "C:\Users\Samo\AppData\Local\Programs\Python\Python35\lib\site-packages\django\contrib\auth\decorators.py", line 23, in _wrapped_view
    return view_func(request, *args, **kwargs)
  File "C:\Users\Samo\Desktop\projekt-tomo\projekt-tomo\web\problems\views.py", line 175, in all_solutions_to_part
    'attempts' : attempts,
  File "C:\Users\Samo\AppData\Local\Programs\Python\Python35\lib\site-packages\django\shortcuts.py", line 67, in render
    template_name, context, request=request, using=using)
  File "C:\Users\Samo\AppData\Local\Programs\Python\Python35\lib\site-packages\django\template\loader.py", line 96, in render_to_string
    template = get_template(template_name, using=using)
  File "C:\Users\Samo\AppData\Local\Programs\Python\Python35\lib\site-packages\django\template\loader.py", line 32, in get_template
    return engine.get_template(template_name, dirs)
  File "C:\Users\Samo\AppData\Local\Programs\Python\Python35\lib\site-packages\django\template\backends\django.py", line 40, in get_template
    return Template(self.engine.get_template(template_name, dirs), self)
  File "C:\Users\Samo\AppData\Local\Programs\Python\Python35\lib\site-packages\django\template\engine.py", line 190, in get_template
    template, origin = self.find_template(template_name, dirs)
  File "C:\Users\Samo\AppData\Local\Programs\Python\Python35\lib\site-packages\django\template\engine.py", line 157, in find_template
    name, template_dirs=dirs, skip=skip,
  File "C:\Users\Samo\AppData\Local\Programs\Python\Python35\lib\site-packages\django\template\loaders\base.py", line 46, in get_template
    contents, origin, origin.template_name, self.engine,
  File "C:\Users\Samo\AppData\Local\Programs\Python\Python35\lib\site-packages\django\template\base.py", line 189, in __init__
    self.nodelist = self.compile_nodelist()
  File "C:\Users\Samo\AppData\Local\Programs\Python\Python35\lib\site-packages\django\template\base.py", line 231, in compile_nodelist
    return parser.parse()
  File "C:\Users\Samo\AppData\Local\Programs\Python\Python35\lib\site-packages\django\template\base.py", line 516, in parse
    raise self.error(token, e)
  File "C:\Users\Samo\AppData\Local\Programs\Python\Python35\lib\site-packages\django\template\base.py", line 514, in parse
    compiled_result = compile_func(self, token)
  File "C:\Users\Samo\AppData\Local\Programs\Python\Python35\lib\site-packages\django\template\loader_tags.py", line 267, in do_extends
    nodelist = parser.parse()
  File "C:\Users\Samo\AppData\Local\Programs\Python\Python35\lib\site-packages\django\template\base.py", line 516, in parse
    raise self.error(token, e)
  File "C:\Users\Samo\AppData\Local\Programs\Python\Python35\lib\site-packages\django\template\base.py", line 514, in parse
    compiled_result = compile_func(self, token)
  File "C:\Users\Samo\AppData\Local\Programs\Python\Python35\lib\site-packages\django\template\loader_tags.py", line 241, in do_block
    nodelist = parser.parse(('endblock',))
  File "C:\Users\Samo\AppData\Local\Programs\Python\Python35\lib\site-packages\django\template\base.py", line 516, in parse
    raise self.error(token, e)
  File "C:\Users\Samo\AppData\Local\Programs\Python\Python35\lib\site-packages\django\template\base.py", line 514, in parse
    compiled_result = compile_func(self, token)
  File "C:\Users\Samo\AppData\Local\Programs\Python\Python35\lib\site-packages\django\template\defaulttags.py", line 886, in do_for
    nodelist_loop = parser.parse(('empty', 'endfor',))
  File "C:\Users\Samo\AppData\Local\Programs\Python\Python35\lib\site-packages\django\template\base.py", line 510, in parse
    self.invalid_block_tag(token, command, parse_until)
  File "C:\Users\Samo\AppData\Local\Programs\Python\Python35\lib\site-packages\django\template\base.py", line 566, in invalid_block_tag
    get_text_list(["'%s'" % p for p in parse_until]),
django.template.exceptions.TemplateSyntaxError: Invalid block tag on line 35: 'attempt.user', expected 'empty' ali 'endfor'. Did you forget to register or load this tag?
Internal Server Error: /problems/view_all/935
Traceback (most recent call last):
  File "C:\Users\Samo\AppData\Local\Programs\Python\Python35\lib\site-packages\django\core\handlers\base.py", line 149, in get_response
    response = self.process_exception_by_middleware(e, request)
  File "C:\Users\Samo\AppData\Local\Programs\Python\Python35\lib\site-packages\django\core\handlers\base.py", line 147, in get_response
    response = wrapped_callback(request, *callback_args, **callback_kwargs)
  File "C:\Users\Samo\AppData\Local\Programs\Python\Python35\lib\site-packages\django\contrib\auth\decorators.py", line 23, in _wrapped_view
    return view_func(request, *args, **kwargs)
  File "C:\Users\Samo\Desktop\projekt-tomo\projekt-tomo\web\problems\views.py", line 175, in all_solutions_to_part
    'attempts' : attempts,
  File "C:\Users\Samo\AppData\Local\Programs\Python\Python35\lib\site-packages\django\shortcuts.py", line 67, in render
    template_name, context, request=request, using=using)
  File "C:\Users\Samo\AppData\Local\Programs\Python\Python35\lib\site-packages\django\template\loader.py", line 96, in render_to_string
    template = get_template(template_name, using=using)
  File "C:\Users\Samo\AppData\Local\Programs\Python\Python35\lib\site-packages\django\template\loader.py", line 32, in get_template
    return engine.get_template(template_name, dirs)
  File "C:\Users\Samo\AppData\Local\Programs\Python\Python35\lib\site-packages\django\template\backends\django.py", line 40, in get_template
    return Template(self.engine.get_template(template_name, dirs), self)
  File "C:\Users\Samo\AppData\Local\Programs\Python\Python35\lib\site-packages\django\template\engine.py", line 190, in get_template
    template, origin = self.find_template(template_name, dirs)
  File "C:\Users\Samo\AppData\Local\Programs\Python\Python35\lib\site-packages\django\template\engine.py", line 157, in find_template
    name, template_dirs=dirs, skip=skip,
  File "C:\Users\Samo\AppData\Local\Programs\Python\Python35\lib\site-packages\django\template\loaders\base.py", line 46, in get_template
    contents, origin, origin.template_name, self.engine,
  File "C:\Users\Samo\AppData\Local\Programs\Python\Python35\lib\site-packages\django\template\base.py", line 189, in __init__
    self.nodelist = self.compile_nodelist()
  File "C:\Users\Samo\AppData\Local\Programs\Python\Python35\lib\site-packages\django\template\base.py", line 231, in compile_nodelist
    return parser.parse()
  File "C:\Users\Samo\AppData\Local\Programs\Python\Python35\lib\site-packages\django\template\base.py", line 516, in parse
    raise self.error(token, e)
  File "C:\Users\Samo\AppData\Local\Programs\Python\Python35\lib\site-packages\django\template\base.py", line 514, in parse
    compiled_result = compile_func(self, token)
  File "C:\Users\Samo\AppData\Local\Programs\Python\Python35\lib\site-packages\django\template\loader_tags.py", line 267, in do_extends
    nodelist = parser.parse()
  File "C:\Users\Samo\AppData\Local\Programs\Python\Python35\lib\site-packages\django\template\base.py", line 516, in parse
    raise self.error(token, e)
  File "C:\Users\Samo\AppData\Local\Programs\Python\Python35\lib\site-packages\django\template\base.py", line 514, in parse
    compiled_result = compile_func(self, token)
  File "C:\Users\Samo\AppData\Local\Programs\Python\Python35\lib\site-packages\django\template\loader_tags.py", line 241, in do_block
    nodelist = parser.parse(('endblock',))
  File "C:\Users\Samo\AppData\Local\Programs\Python\Python35\lib\site-packages\django\template\base.py", line 516, in parse
    raise self.error(token, e)
  File "C:\Users\Samo\AppData\Local\Programs\Python\Python35\lib\site-packages\django\template\base.py", line 514, in parse
    compiled_result = compile_func(self, token)
  File "C:\Users\Samo\AppData\Local\Programs\Python\Python35\lib\site-packages\django\template\defaulttags.py", line 886, in do_for
    nodelist_loop = parser.parse(('empty', 'endfor',))
  File "C:\Users\Samo\AppData\Local\Programs\Python\Python35\lib\site-packages\django\template\base.py", line 516, in parse
    raise self.error(token, e)
  File "C:\Users\Samo\AppData\Local\Programs\Python\Python35\lib\site-packages\django\template\base.py", line 514, in parse
    compiled_result = compile_func(self, token)
  File "C:\Users\Samo\AppData\Local\Programs\Python\Python35\lib\site-packages\django\template\defaulttags.py", line 1042, in do_if
    nodelist = parser.parse(('endif',))
  File "C:\Users\Samo\AppData\Local\Programs\Python\Python35\lib\site-packages\django\template\base.py", line 516, in parse
    raise self.error(token, e)
  File "C:\Users\Samo\AppData\Local\Programs\Python\Python35\lib\site-packages\django\template\base.py", line 514, in parse
    compiled_result = compile_func(self, token)
  File "C:\Users\Samo\AppData\Local\Programs\Python\Python35\lib\site-packages\django\template\defaulttags.py", line 885, in do_for
    sequence = parser.compile_filter(bits[in_index + 1])
  File "C:\Users\Samo\AppData\Local\Programs\Python\Python35\lib\site-packages\django\template\base.py", line 601, in compile_filter
    return FilterExpression(token, self)
  File "C:\Users\Samo\AppData\Local\Programs\Python\Python35\lib\site-packages\django\template\base.py", line 701, in __init__
    "from '%s'" % (token[upto:], token))
django.template.exceptions.TemplateSyntaxError: Could not parse the remainder: '(',')' from 'attempt.feedback.split(',')'
Internal Server Error: /problems/view_all/935
Traceback (most recent call last):
  File "C:\Users\Samo\AppData\Local\Programs\Python\Python35\lib\site-packages\django\core\handlers\base.py", line 149, in get_response
    response = self.process_exception_by_middleware(e, request)
  File "C:\Users\Samo\AppData\Local\Programs\Python\Python35\lib\site-packages\django\core\handlers\base.py", line 147, in get_response
    response = wrapped_callback(request, *callback_args, **callback_kwargs)
  File "C:\Users\Samo\AppData\Local\Programs\Python\Python35\lib\site-packages\django\contrib\auth\decorators.py", line 23, in _wrapped_view
    return view_func(request, *args, **kwargs)
  File "C:\Users\Samo\Desktop\projekt-tomo\projekt-tomo\web\problems\views.py", line 178, in all_solutions_to_part
    'attempts' : attempts,
  File "C:\Users\Samo\AppData\Local\Programs\Python\Python35\lib\site-packages\django\shortcuts.py", line 67, in render
    template_name, context, request=request, using=using)
  File "C:\Users\Samo\AppData\Local\Programs\Python\Python35\lib\site-packages\django\template\loader.py", line 96, in render_to_string
    template = get_template(template_name, using=using)
  File "C:\Users\Samo\AppData\Local\Programs\Python\Python35\lib\site-packages\django\template\loader.py", line 32, in get_template
    return engine.get_template(template_name, dirs)
  File "C:\Users\Samo\AppData\Local\Programs\Python\Python35\lib\site-packages\django\template\backends\django.py", line 40, in get_template
    return Template(self.engine.get_template(template_name, dirs), self)
  File "C:\Users\Samo\AppData\Local\Programs\Python\Python35\lib\site-packages\django\template\engine.py", line 190, in get_template
    template, origin = self.find_template(template_name, dirs)
  File "C:\Users\Samo\AppData\Local\Programs\Python\Python35\lib\site-packages\django\template\engine.py", line 157, in find_template
    name, template_dirs=dirs, skip=skip,
  File "C:\Users\Samo\AppData\Local\Programs\Python\Python35\lib\site-packages\django\template\loaders\base.py", line 46, in get_template
    contents, origin, origin.template_name, self.engine,
  File "C:\Users\Samo\AppData\Local\Programs\Python\Python35\lib\site-packages\django\template\base.py", line 189, in __init__
    self.nodelist = self.compile_nodelist()
  File "C:\Users\Samo\AppData\Local\Programs\Python\Python35\lib\site-packages\django\template\base.py", line 231, in compile_nodelist
    return parser.parse()
  File "C:\Users\Samo\AppData\Local\Programs\Python\Python35\lib\site-packages\django\template\base.py", line 516, in parse
    raise self.error(token, e)
  File "C:\Users\Samo\AppData\Local\Programs\Python\Python35\lib\site-packages\django\template\base.py", line 514, in parse
    compiled_result = compile_func(self, token)
  File "C:\Users\Samo\AppData\Local\Programs\Python\Python35\lib\site-packages\django\template\loader_tags.py", line 267, in do_extends
    nodelist = parser.parse()
  File "C:\Users\Samo\AppData\Local\Programs\Python\Python35\lib\site-packages\django\template\base.py", line 516, in parse
    raise self.error(token, e)
  File "C:\Users\Samo\AppData\Local\Programs\Python\Python35\lib\site-packages\django\template\base.py", line 514, in parse
    compiled_result = compile_func(self, token)
  File "C:\Users\Samo\AppData\Local\Programs\Python\Python35\lib\site-packages\django\template\loader_tags.py", line 241, in do_block
    nodelist = parser.parse(('endblock',))
  File "C:\Users\Samo\AppData\Local\Programs\Python\Python35\lib\site-packages\django\template\base.py", line 516, in parse
    raise self.error(token, e)
  File "C:\Users\Samo\AppData\Local\Programs\Python\Python35\lib\site-packages\django\template\base.py", line 514, in parse
    compiled_result = compile_func(self, token)
  File "C:\Users\Samo\AppData\Local\Programs\Python\Python35\lib\site-packages\django\template\defaulttags.py", line 886, in do_for
    nodelist_loop = parser.parse(('empty', 'endfor',))
  File "C:\Users\Samo\AppData\Local\Programs\Python\Python35\lib\site-packages\django\template\base.py", line 516, in parse
    raise self.error(token, e)
  File "C:\Users\Samo\AppData\Local\Programs\Python\Python35\lib\site-packages\django\template\base.py", line 514, in parse
    compiled_result = compile_func(self, token)
  File "C:\Users\Samo\AppData\Local\Programs\Python\Python35\lib\site-packages\django\template\defaulttags.py", line 1042, in do_if
    nodelist = parser.parse(('endif',))
  File "C:\Users\Samo\AppData\Local\Programs\Python\Python35\lib\site-packages\django\template\base.py", line 516, in parse
    raise self.error(token, e)
  File "C:\Users\Samo\AppData\Local\Programs\Python\Python35\lib\site-packages\django\template\base.py", line 514, in parse
    compiled_result = compile_func(self, token)
  File "C:\Users\Samo\AppData\Local\Programs\Python\Python35\lib\site-packages\django\template\defaulttags.py", line 885, in do_for
    sequence = parser.compile_filter(bits[in_index + 1])
  File "C:\Users\Samo\AppData\Local\Programs\Python\Python35\lib\site-packages\django\template\base.py", line 601, in compile_filter
    return FilterExpression(token, self)
  File "C:\Users\Samo\AppData\Local\Programs\Python\Python35\lib\site-packages\django\template\base.py", line 701, in __init__
    "from '%s'" % (token[upto:], token))
django.template.exceptions.TemplateSyntaxError: Could not parse the remainder: '(',')' from 'attempt.feedback.split(',')'
Internal Server Error: /problems/view_all/935
Traceback (most recent call last):
  File "C:\Users\Samo\AppData\Local\Programs\Python\Python35\lib\site-packages\django\template\smartif.py", line 177, in translate_token
    op = OPERATORS[token]
KeyError: '["[]"]'

During handling of the above exception, another exception occurred:

Traceback (most recent call last):
  File "C:\Users\Samo\AppData\Local\Programs\Python\Python35\lib\site-packages\django\core\handlers\base.py", line 149, in get_response
    response = self.process_exception_by_middleware(e, request)
  File "C:\Users\Samo\AppData\Local\Programs\Python\Python35\lib\site-packages\django\core\handlers\base.py", line 147, in get_response
    response = wrapped_callback(request, *callback_args, **callback_kwargs)
  File "C:\Users\Samo\AppData\Local\Programs\Python\Python35\lib\site-packages\django\contrib\auth\decorators.py", line 23, in _wrapped_view
    return view_func(request, *args, **kwargs)
  File "C:\Users\Samo\Desktop\projekt-tomo\projekt-tomo\web\problems\views.py", line 178, in all_solutions_to_part
    'attempts' : attempts,
  File "C:\Users\Samo\AppData\Local\Programs\Python\Python35\lib\site-packages\django\shortcuts.py", line 67, in render
    template_name, context, request=request, using=using)
  File "C:\Users\Samo\AppData\Local\Programs\Python\Python35\lib\site-packages\django\template\loader.py", line 96, in render_to_string
    template = get_template(template_name, using=using)
  File "C:\Users\Samo\AppData\Local\Programs\Python\Python35\lib\site-packages\django\template\loader.py", line 32, in get_template
    return engine.get_template(template_name, dirs)
  File "C:\Users\Samo\AppData\Local\Programs\Python\Python35\lib\site-packages\django\template\backends\django.py", line 40, in get_template
    return Template(self.engine.get_template(template_name, dirs), self)
  File "C:\Users\Samo\AppData\Local\Programs\Python\Python35\lib\site-packages\django\template\engine.py", line 190, in get_template
    template, origin = self.find_template(template_name, dirs)
  File "C:\Users\Samo\AppData\Local\Programs\Python\Python35\lib\site-packages\django\template\engine.py", line 157, in find_template
    name, template_dirs=dirs, skip=skip,
  File "C:\Users\Samo\AppData\Local\Programs\Python\Python35\lib\site-packages\django\template\loaders\base.py", line 46, in get_template
    contents, origin, origin.template_name, self.engine,
  File "C:\Users\Samo\AppData\Local\Programs\Python\Python35\lib\site-packages\django\template\base.py", line 189, in __init__
    self.nodelist = self.compile_nodelist()
  File "C:\Users\Samo\AppData\Local\Programs\Python\Python35\lib\site-packages\django\template\base.py", line 231, in compile_nodelist
    return parser.parse()
  File "C:\Users\Samo\AppData\Local\Programs\Python\Python35\lib\site-packages\django\template\base.py", line 516, in parse
    raise self.error(token, e)
  File "C:\Users\Samo\AppData\Local\Programs\Python\Python35\lib\site-packages\django\template\base.py", line 514, in parse
    compiled_result = compile_func(self, token)
  File "C:\Users\Samo\AppData\Local\Programs\Python\Python35\lib\site-packages\django\template\loader_tags.py", line 267, in do_extends
    nodelist = parser.parse()
  File "C:\Users\Samo\AppData\Local\Programs\Python\Python35\lib\site-packages\django\template\base.py", line 516, in parse
    raise self.error(token, e)
  File "C:\Users\Samo\AppData\Local\Programs\Python\Python35\lib\site-packages\django\template\base.py", line 514, in parse
    compiled_result = compile_func(self, token)
  File "C:\Users\Samo\AppData\Local\Programs\Python\Python35\lib\site-packages\django\template\loader_tags.py", line 241, in do_block
    nodelist = parser.parse(('endblock',))
  File "C:\Users\Samo\AppData\Local\Programs\Python\Python35\lib\site-packages\django\template\base.py", line 516, in parse
    raise self.error(token, e)
  File "C:\Users\Samo\AppData\Local\Programs\Python\Python35\lib\site-packages\django\template\base.py", line 514, in parse
    compiled_result = compile_func(self, token)
  File "C:\Users\Samo\AppData\Local\Programs\Python\Python35\lib\site-packages\django\template\defaulttags.py", line 886, in do_for
    nodelist_loop = parser.parse(('empty', 'endfor',))
  File "C:\Users\Samo\AppData\Local\Programs\Python\Python35\lib\site-packages\django\template\base.py", line 516, in parse
    raise self.error(token, e)
  File "C:\Users\Samo\AppData\Local\Programs\Python\Python35\lib\site-packages\django\template\base.py", line 514, in parse
    compiled_result = compile_func(self, token)
  File "C:\Users\Samo\AppData\Local\Programs\Python\Python35\lib\site-packages\django\template\defaulttags.py", line 1027, in do_if
    condition = TemplateIfParser(parser, bits).parse()
  File "C:\Users\Samo\AppData\Local\Programs\Python\Python35\lib\site-packages\django\template\defaulttags.py", line 959, in __init__
    super(TemplateIfParser, self).__init__(*args, **kwargs)
  File "C:\Users\Samo\AppData\Local\Programs\Python\Python35\lib\site-packages\django\template\smartif.py", line 168, in __init__
    mapped_tokens.append(self.translate_token(token))
  File "C:\Users\Samo\AppData\Local\Programs\Python\Python35\lib\site-packages\django\template\smartif.py", line 179, in translate_token
    return self.create_var(token)
  File "C:\Users\Samo\AppData\Local\Programs\Python\Python35\lib\site-packages\django\template\defaulttags.py", line 962, in create_var
    return TemplateLiteral(self.template_parser.compile_filter(value), value)
  File "C:\Users\Samo\AppData\Local\Programs\Python\Python35\lib\site-packages\django\template\base.py", line 601, in compile_filter
    return FilterExpression(token, self)
  File "C:\Users\Samo\AppData\Local\Programs\Python\Python35\lib\site-packages\django\template\base.py", line 701, in __init__
    "from '%s'" % (token[upto:], token))
django.template.exceptions.TemplateSyntaxError: Could not parse the remainder: '["[]"]' from '["[]"]'
Internal Server Error: /problems/view_all/935
Traceback (most recent call last):
  File "C:\Users\Samo\AppData\Local\Programs\Python\Python35\lib\site-packages\django\core\handlers\base.py", line 149, in get_response
    response = self.process_exception_by_middleware(e, request)
  File "C:\Users\Samo\AppData\Local\Programs\Python\Python35\lib\site-packages\django\core\handlers\base.py", line 147, in get_response
    response = wrapped_callback(request, *callback_args, **callback_kwargs)
  File "C:\Users\Samo\AppData\Local\Programs\Python\Python35\lib\site-packages\django\contrib\auth\decorators.py", line 23, in _wrapped_view
    return view_func(request, *args, **kwargs)
  File "C:\Users\Samo\Desktop\projekt-tomo\projekt-tomo\web\problems\views.py", line 178, in all_solutions_to_part
    'attempts' : attempts,
  File "C:\Users\Samo\AppData\Local\Programs\Python\Python35\lib\site-packages\django\shortcuts.py", line 67, in render
    template_name, context, request=request, using=using)
  File "C:\Users\Samo\AppData\Local\Programs\Python\Python35\lib\site-packages\django\template\loader.py", line 96, in render_to_string
    template = get_template(template_name, using=using)
  File "C:\Users\Samo\AppData\Local\Programs\Python\Python35\lib\site-packages\django\template\loader.py", line 32, in get_template
    return engine.get_template(template_name, dirs)
  File "C:\Users\Samo\AppData\Local\Programs\Python\Python35\lib\site-packages\django\template\backends\django.py", line 40, in get_template
    return Template(self.engine.get_template(template_name, dirs), self)
  File "C:\Users\Samo\AppData\Local\Programs\Python\Python35\lib\site-packages\django\template\engine.py", line 190, in get_template
    template, origin = self.find_template(template_name, dirs)
  File "C:\Users\Samo\AppData\Local\Programs\Python\Python35\lib\site-packages\django\template\engine.py", line 157, in find_template
    name, template_dirs=dirs, skip=skip,
  File "C:\Users\Samo\AppData\Local\Programs\Python\Python35\lib\site-packages\django\template\loaders\base.py", line 46, in get_template
    contents, origin, origin.template_name, self.engine,
  File "C:\Users\Samo\AppData\Local\Programs\Python\Python35\lib\site-packages\django\template\base.py", line 189, in __init__
    self.nodelist = self.compile_nodelist()
  File "C:\Users\Samo\AppData\Local\Programs\Python\Python35\lib\site-packages\django\template\base.py", line 231, in compile_nodelist
    return parser.parse()
  File "C:\Users\Samo\AppData\Local\Programs\Python\Python35\lib\site-packages\django\template\base.py", line 516, in parse
    raise self.error(token, e)
  File "C:\Users\Samo\AppData\Local\Programs\Python\Python35\lib\site-packages\django\template\base.py", line 514, in parse
    compiled_result = compile_func(self, token)
  File "C:\Users\Samo\AppData\Local\Programs\Python\Python35\lib\site-packages\django\template\loader_tags.py", line 267, in do_extends
    nodelist = parser.parse()
  File "C:\Users\Samo\AppData\Local\Programs\Python\Python35\lib\site-packages\django\template\base.py", line 516, in parse
    raise self.error(token, e)
  File "C:\Users\Samo\AppData\Local\Programs\Python\Python35\lib\site-packages\django\template\base.py", line 514, in parse
    compiled_result = compile_func(self, token)
  File "C:\Users\Samo\AppData\Local\Programs\Python\Python35\lib\site-packages\django\template\loader_tags.py", line 241, in do_block
    nodelist = parser.parse(('endblock',))
  File "C:\Users\Samo\AppData\Local\Programs\Python\Python35\lib\site-packages\django\template\base.py", line 516, in parse
    raise self.error(token, e)
  File "C:\Users\Samo\AppData\Local\Programs\Python\Python35\lib\site-packages\django\template\base.py", line 514, in parse
    compiled_result = compile_func(self, token)
  File "C:\Users\Samo\AppData\Local\Programs\Python\Python35\lib\site-packages\django\template\defaulttags.py", line 886, in do_for
    nodelist_loop = parser.parse(('empty', 'endfor',))
  File "C:\Users\Samo\AppData\Local\Programs\Python\Python35\lib\site-packages\django\template\base.py", line 516, in parse
    raise self.error(token, e)
  File "C:\Users\Samo\AppData\Local\Programs\Python\Python35\lib\site-packages\django\template\base.py", line 514, in parse
    compiled_result = compile_func(self, token)
  File "C:\Users\Samo\AppData\Local\Programs\Python\Python35\lib\site-packages\django\template\defaulttags.py", line 1042, in do_if
    nodelist = parser.parse(('endif',))
  File "C:\Users\Samo\AppData\Local\Programs\Python\Python35\lib\site-packages\django\template\base.py", line 487, in parse
    raise self.error(token, e)
  File "C:\Users\Samo\AppData\Local\Programs\Python\Python35\lib\site-packages\django\template\base.py", line 485, in parse
    filter_expression = self.compile_filter(token.contents)
  File "C:\Users\Samo\AppData\Local\Programs\Python\Python35\lib\site-packages\django\template\base.py", line 601, in compile_filter
    return FilterExpression(token, self)
  File "C:\Users\Samo\AppData\Local\Programs\Python\Python35\lib\site-packages\django\template\base.py", line 695, in __init__
    filter_func = parser.find_filter(filter_name)
  File "C:\Users\Samo\AppData\Local\Programs\Python\Python35\lib\site-packages\django\template\base.py", line 607, in find_filter
    raise TemplateSyntaxError("Invalid filter: '%s'" % filter_name)
django.template.exceptions.TemplateSyntaxError: Invalid filter: 'json'
